Workbook

Sheet Отчет АРКА
F25: ="Еженедельный отчет" -> Еженедельный отчет
F26: ARKA
F28: ='Лист1'!B1 -> КолоСС МТФ Рогожино - 1, 2
A38: ЕЖЕНЕДЕЛЬНЫЙ ОТЧЕТ 09.08.2026-15.08.2026
A41: ОБЩЕЕ
G44: ='Лист1'!B2 -> 4446 | J44: ='Лист1'!B3 -> 50 % | N44: ='Лист1'!B4 -> 35 % | Q44: ='Лист1'!B5 -> 374 | T44: ='Лист1'!B6 -> 32
F46: Коров | I46: Стельных | M46: Первотёлок | P46: DNB | S46: Средний надой
A48: ВОСПРОИЗВОДСТВО
G51: ='Лист1'!B7 -> 188.7 | K51: ='Лист1'!B10 -> 35 % | P51: ='Лист1'!B8 -> 57 % | U51: ='Лист1'!B9 -> 19 %
F53: DIM | J53: CR | O53: HD | T53: PR
A55: ЗДОРОВЬЕ
H58: ='Лист1'!B12 -> 0.14344685 | N58: ='Лист1'!B13 -> 0.010252905 | T58: ='Лист1'!B14 -> 8 %
G60: Выбытие до 60 дня коров | M60: Сохранность телок за год | S60: Брак коров
B68: www.dfsoft.ru | E68: ="+7-800-707-7-305" -> +7-800-707-7-305 | I68: dc305@dc305.ru
A71: ВЫПОЛНЕНИЕ ТЕХНОЛОГИЧЕСКОЙ КАРТЫ
B73: Выполнение технологической карты
B74: ='Лист1'!A18 -> Задача | D74: ='Лист1'!B18 -> Вс | E74: ='Лист1'!C18 -> Пн | F74: ='Лист1'!D18 -> Вт | G74: ='Лист1'!E18 -> Ср | H74: ='Лист1'!F18 -> Чт | I74: ='Лист1'!G18 -> Пт | J74: ='Лист1'!H18 -> Сб | L74: Запуск по дням стельности | T74: 1-е осеменение
B75: ='Лист1'!A19 -> G7G | D75: ='Лист1'!B19 -> 0 | E75: ='Лист1'!C19 -> 0 | F75: ='Лист1'!D19 -> 0 | G75: ='Лист1'!E19 -> 0 | H75: ='Лист1'!F19 -> 0 | I75: ='Лист1'!G19 -> 0 | J75: ='Лист1'!H19 -> 59
B76: ='Лист1'!A20 -> Ресинх | D76: ='Лист1'!B20 -> 0 | E76: ='Лист1'!C20 -> 222 | F76: ='Лист1'!D20 -> 0 | G76: ='Лист1'!E20 -> 0 | H76: ='Лист1'!F20 -> 0 | I76: ='Лист1'!G20 -> 0 | J76: ='Лист1'!H20 -> 0
B77: ='Лист1'!A21 -> Аборт | D77: ='Лист1'!B21 -> 0 | E77: ='Лист1'!C21 -> 9 | F77: ='Лист1'!D21 -> 0 | G77: ='Лист1'!E21 -> 0 | H77: ='Лист1'!F21 -> 0 | I77: ='Лист1'!G21 -> 0 | J77: ='Лист1'!H21 -> 0
B78: ='Лист1'!A22 -> Брак | D78: ='Лист1'!B22 -> 0 | E78: ='Лист1'!C22 -> 9 | F78: ='Лист1'!D22 -> 0 | G78: ='Лист1'!E22 -> 0 | H78: ='Лист1'!F22 -> 2 | I78: ='Лист1'!G22 -> 3 | J78: ='Лист1'!H22 -> 0
B79: ='Лист1'!A23 -> Нестельная | D79: ='Лист1'!B23 -> 0 | E79: ='Лист1'!C23 -> 116 | F79: ='Лист1'!D23 -> 0 | G79: ='Лист1'!E23 -> 0 | H79: ='Лист1'!F23 -> 0 | I79: ='Лист1'!G23 -> 0 | J79: ='Лист1'!H23 -> 0
B80: ='Лист1'!A24 -> Отел | D80: ='Лист1'!B24 -> 17 | E80: ='Лист1'!C24 -> 14 | F80: ='Лист1'!D24 -> 15 | G80: ='Лист1'!E24 -> 8 | H80: ='Лист1'!F24 -> 13 | I80: ='Лист1'!G24 -> 16 | J80: ='Лист1'!H24 -> 3
B81: ='Лист1'!A25 -> Падёж | D81: ='Лист1'!B25 -> 1 | E81: ='Лист1'!C25 -> 0 | F81: ='Лист1'!D25 -> 1 | G81: ='Лист1'!E25 -> 1 | H81: ='Лист1'!F25 -> 1 | I81: ='Лист1'!G25 -> 0 | J81: ='Лист1'!H25 -> 0
B82: ='Лист1'!A26 -> Стельная | D82: ='Лист1'!B26 -> 0 | E82: ='Лист1'!C26 -> 213 | F82: ='Лист1'!D26 -> 0 | G82: ='Лист1'!E26 -> 0 | H82: ='Лист1'!F26 -> 0 | I82: ='Лист1'!G26 -> 1 | J82: ='Лист1'!H26 -> 0
B83: ='Лист1'!A27 -> Взвешивание | D83: ='Лист1'!B27 -> 0 | E83: ='Лист1'!C27 -> 0 | F83: ='Лист1'!D27 -> 0 | G83: ='Лист1'!E27 -> 0 | H83: ='Лист1'!F27 -> 0 | I83: ='Лист1'!G27 -> 0 | J83: ='Лист1'!H27 -> 0
B84: ='Лист1'!A28 -> Забой | D84: ='Лист1'!B28 -> 0 | E84: ='Лист1'!C28 -> 0 | F84: ='Лист1'!D28 -> 0 | G84: ='Лист1'!E28 -> 0 | H84: ='Лист1'!F28 -> 0 | I84: ='Лист1'!G28 -> 0 | J84: ='Лист1'!H28 -> 0
B85: ='Лист1'!A29 -> Обезроживание | D85: ='Лист1'!B29 -> 0 | E85: ='Лист1'!C29 -> 0 | F85: ='Лист1'!D29 -> 0 | G85: ='Лист1'!E29 -> 0 | H85: ='Лист1'!F29 -> 0 | I85: ='Лист1'!G29 -> 0 | J85: ='Лист1'!H29 -> 0
B86: ='Лист1'!A30 -> Осеменение | D86: ='Лист1'!B30 -> 0 | E86: ='Лист1'!C30 -> 2 | F86: ='Лист1'!D30 -> 0 | G86: ='Лист1'!E30 -> 0 | H86: ='Лист1'!F30 -> 107 | I86: ='Лист1'!G30 -> 80 | J86: ='Лист1'!H30 -> 0
B87: ='Лист1'!A31 -> Перебирковка | D87: ='Лист1'!B31 -> 0 | E87: ='Лист1'!C31 -> 0 | F87: ='Лист1'!D31 -> 0 | G87: ='Лист1'!E31 -> 0 | H87: ='Лист1'!F31 -> 0 | I87: ='Лист1'!G31 -> 0 | J87: ='Лист1'!H31 -> 0 | L87: Стельность | T87: 2-е осеменение
B88: ='Лист1'!A32 -> Перевод | D88: ='Лист1'!B32 -> 177 | E88: ='Лист1'!C32 -> 113 | F88: ='Лист1'!D32 -> 192 | G88: ='Лист1'!E32 -> 233 | H88: ='Лист1'!F32 -> 104 | I88: ='Лист1'!G32 -> 100 | J88: ='Лист1'!H32 -> 19
B89: ='Лист1'!A33 -> Поздний сухостой | D89: ='Лист1'!B33 -> 0 | E89: ='Лист1'!C33 -> 0 | F89: ='Лист1'!D33 -> 50 | G89: ='Лист1'!E33 -> 0 | H89: ='Лист1'!F33 -> 31 | I89: ='Лист1'!G33 -> 0 | J89: ='Лист1'!H33 -> 0
B90: ='Лист1'!A34 -> Сухостой | D90: ='Лист1'!B34 -> 0 | E90: ='Лист1'!C34 -> 0 | F90: ='Лист1'!D34 -> 0 | G90: ='Лист1'!E34 -> 77 | H90: ='Лист1'!F34 -> 0 | I90: ='Лист1'!G34 -> 0 | J90: ='Лист1'!H34 -> 0
B91: ='Лист1'!A35 -> Продажа | D91: ='Лист1'!B35 -> 1 | E91: ='Лист1'!C35 -> 6 | F91: ='Лист1'!D35 -> 6 | G91: ='Лист1'!E35 -> 6 | H91: ='Лист1'!F35 -> 53 | I91: ='Лист1'!G35 -> 53 | J91: ='Лист1'!H35 -> 0
B92: ='Лист1'!A36 -> Диарея | D92: ='Лист1'!B36 -> 0 | E92: ='Лист1'!C36 -> 0 | F92: ='Лист1'!D36 -> 0 | G92: ='Лист1'!E36 -> 0 | H92: ='Лист1'!F36 -> 0 | I92: ='Лист1'!G36 -> 0 | J92: ='Лист1'!H36 -> 0
B93: ='Лист1'!A37 -> Кетоз | D93: ='Лист1'!B37 -> 0 | E93: ='Лист1'!C37 -> 0 | F93: ='Лист1'!D37 -> 0 | G93: ='Лист1'!E37 -> 0 | H93: ='Лист1'!F37 -> 0 | I93: ='Лист1'!G37 -> 0 | J93: ='Лист1'!H37 -> 0
B94: ='Лист1'!A38 -> Мастит | D94: ='Лист1'!B38 -> 16 | E94: ='Лист1'!C38 -> 15 | F94: ='Лист1'!D38 -> 23 | G94: ='Лист1'!E38 -> 16 | H94: ='Лист1'!F38 -> 17 | I94: ='Лист1'!G38 -> 15 | J94: ='Лист1'!H38 -> 0
B95: ='Лист1'!A39 -> Молочная лихорадка, Парез | D95: ='Лист1'!B39 -> 3 | E95: ='Лист1'!C39 -> 1 | F95: ='Лист1'!D39 -> 2 | G95: ='Лист1'!E39 -> 1 | H95: ='Лист1'!F39 -> 0 | I95: ='Лист1'!G39 -> 1 | J95: ='Лист1'!H39 -> 0
B96: ='Лист1'!A40 -> Послеродовой парез | D96: ='Лист1'!B40 -> 0 | E96: ='Лист1'!C40 -> 0 | F96: ='Лист1'!D40 -> 0 | G96: ='Лист1'!E40 -> 0 | H96: ='Лист1'!F40 -> 0 | I96: ='Лист1'!G40 -> 0 | J96: ='Лист1'!H40 -> 0
B97: ='Лист1'!A41 -> Субклинический мастит | D97: ='Лист1'!B41 -> 0 | E97: ='Лист1'!C41 -> 0 | F97: ='Лист1'!D41 -> 0 | G97: ='Лист1'!E41 -> 0 | H97: ='Лист1'!F41 -> 0 | I97: ='Лист1'!G41 -> 0 | J97: ='Лист1'!H41 -> 0
...

Sheet Лист1
A1: Название хозяйства | B1: КолоСС МТФ Рогожино - 1, 2 | C1: Вставить из показателей ---> | D1: Кол-во коров в стаде | E1: 4446
A2: Коров | B2: =E1 -> 4446 | C2: Ссылка на отчет из Арки | D2: % Стельных | E2: 50 % | F2: от 55 %
A3: Стельных | B3: =E2 -> 50 % | D3: % Первотелок | E3: 35 % | G3: =E1:E7 -> 35 %
A4: Первотелок | B4: =E3 -> 35 % | D4: Кол-во БРАК коровы | E4: 374
A5: БРАК | B5: =E4 -> 374 | D5: Средний надой ДЗ | E5: 32
A6: Средний надой | B6: =E5 -> 32 | D6: Средние дни в доении (без сух.) | E6: 188.7
A7: DIM | B7: =E6 -> 188.7 | D7: % Брака коровы | E7: 8 %
A8: HD | B8: =D9 -> 57 % | C8: Ссылка на отчет из Арки
A9: PR | B9: =G9 -> 19 % | D9: 57 % | E9: 852 | F9: 166 | G9: 19 % | H9: 35 % | I9: 0
A10: CR | B10: =H9 -> 35 %
A11: Стельных осем по HT телок | B11: 0
A12: Выбытие до 60 дня коров | B12: =1-'Выбытие до 60 дней за год'!D14 -> 0.14344685
A13: Сохранность за год телят | B13: ='Сохранность молодняка'!D8 -> 0.010252905
A14: Брак коров | B14: =E7 -> 8 %
A15: Что-то еще | B15: 0
A17: Ссылка на отчет в Арке
A18: Задача | B18: Вс | C18: Пн | D18: Вт | E18: Ср | F18: Чт | G18: Пт | H18: Сб | K18: Сб | L18: Вс
A19: G7G | B19: 0 | C19: 0 | D19: 0 | E19: 0 | F19: 0 | G19: 0 | H19: 59
A20: Ресинх | B20: 0 | C20: 222 | D20: 0 | E20: 0 | F20: 0 | G20: 0 | H20: 0
A21: Аборт | B21: 0 | C21: 9 | D21: 0 | E21: 0 | F21: 0 | G21: 0 | H21: 0
A22: Брак | B22: 0 | C22: 9 | D22: 0 | E22: 0 | F22: 2 | G22: 3 | H22: 0
A23: Нестельная | B23: 0 | C23: 116 | D23: 0 | E23: 0 | F23: 0 | G23: 0 | H23: 0
A24: Отел | B24: 17 | C24: 14 | D24: 15 | E24: 8 | F24: 13 | G24: 16 | H24: 3
A25: Падёж | B25: 1 | C25: 0 | D25: 1 | E25: 1 | F25: 1 | G25: 0 | H25: 0
A26: Стельная | B26: 0 | C26: 213 | D26: 0 | E26: 0 | F26: 0 | G26: 1 | H26: 0
A27: Взвешивание | B27: 0 | C27: 0 | D27: 0 | E27: 0 | F27: 0 | G27: 0 | H27: 0 | L27: 29 | M27: 0 | N27: 0 | O27: 0 | P27: 0 | Q27: 0
A28: Забой | B28: 0 | C28: 0 | D28: 0 | E28: 0 | F28: 0 | G28: 0 | H28: 0
A29: Обезроживание | B29: 0 | C29: 0 | D29: 0 | E29: 0 | F29: 0 | G29: 0 | H29: 0
A30: Осеменение | B30: 0 | C30: 2 | D30: 0 | E30: 0 | F30: 107 | G30: 80 | H30: 0
A31: Перебирковка | B31: 0 | C31: 0 | D31: 0 | E31: 0 | F31: 0 | G31: 0 | H31: 0
A32: Перевод | B32: 177 | C32: 113 | D32: 192 | E32: 233 | F32: 104 | G32: 100 | H32: 19
A33: Поздний сухостой | B33: 0 | C33: 0 | D33: 50 | E33: 0 | F33: 31 | G33: 0 | H33: 0
A34: Сухостой | B34: 0 | C34: 0 | D34: 0 | E34: 77 | F34: 0 | G34: 0 | H34: 0
A35: Продажа | B35: 1 | C35: 6 | D35: 6 | E35: 6 | F35: 53 | G35: 53 | H35: 0
A36: Диарея | B36: 0 | C36: 0 | D36: 0 | E36: 0 | F36: 0 | G36: 0 | H36: 0
A37: Кетоз | B37: 0 | C37: 0 | D37: 0 | E37: 0 | F37: 0 | G37: 0 | H37: 0
A38: Мастит | B38: 16 | C38: 15 | D38: 23 | E38: 16 | F38: 17 | G38: 15 | H38: 0
A39: Молочная лихорадка, Парез | B39: 3 | C39: 1 | D39: 2 | E39: 1 | F39: 0 | G39: 1 | H39: 0
... A44: Итого | B44: 224 | C44: 748 | D44: 312 | E44: 363 | F44: 352 | G44: 283 | H44: 81

Sheet Лист2
A2: Стельность | B2: Ссылка на отчет в Арке
A3: День с осеменения | B3: Нестельная | C3: Стельная
A4: 32 | B4: 73 | C4: 47
A5: 34 | B5: 1 | C5: 0
A6: 38 | B6: 30 | C6: 17
A7: 39 | B7: 2 | C7: 3
A8: 52 | B8: 3 | C8: 0
A9: 53 | B9: 6 | C9: 0
A10: 56 | B10: 1 | C10: 0
A11: 63 | B11: 0 | C11: 7
A12: 66 | B12: 0 | C12: 28
A13: 67 | B13: 0 | C13: 38
A14: 151 | B14: 0 | C14: 1
A15: 186 | B15: 0 | C15: 1
... A20: 228 | B20: 0 | C20: 28
A34: День с осеменения | B34: Сухостой | D34: Ссылка на отчет в Арке
A35: 153 | B35: 1
A36: 216 | B36: 2
A37: 229 | B37: 36
A38: 230 | B38: 26
A39: 233 | B39: 8
A40: 236 | B40: 1
A41: 237 | B41: 1
A42: 240 | B42: 1
A43: 243 | B43: 1

Sheet 1-е ИО
A1: ID | B1: HDAT | C1: DIMFB | D1: Ссылка на отчет в Арке
A2: 1479 | B2: 46248 | C2: 75
A3: 4926 | B3: 46248 | C3: 73
A4: 6230 | B4: 46247 | C4: 72
A5: 9061 | B5: 46248 | C5: 74
A6: 10718 | B6: 46248 | C6: 75
A7: 16541 | B7: 46247 | C7: 72
A8: 17056 | B8: 46247 | C8: 102
A9: 17801 | B9: 46248 | C9: 71
A10: 32964 | B10: 46248 | C10: 73
A11: 75466 | B11: 46248 | C11: 72
A12: 80148 | B12: 46247 | C12: 76
A13: 94487 | B13: 46248 | C13: 74
... A88: 720051 | B88: 46248 | C88: 76

Sheet 2-е ИО
A1: ID | B1: HDAT | C1: DIMSB | D1: Ссылка на отчет в Арке
A2: 9198 | B2: 46247 | C2: 113
A3: 14368 | B3: 46247 | C3: 116
A4: 16546 | B4: 46247 | C4: 116
A5: 16743 | B5: 46247 | C5: 112
A6: 17523 | B6: 46247 | C6: 125
A7: 18038 | B7: 46247 | C7: 114
A8: 52557 | B8: 46247 | C8: 116
A9: 90390 | B9: 46247 | C9: 116
A10: 100951 | B10: 46247 | C10: 152
A11: 100968 | B11: 46247 | C11: 117
A12: 102053 | B12: 46247 | C12: 111
A13: 102665 | B13: 46247 | C13: 112
... A30: 896945 | B30: 46247 | C30: 114

Sheet Результат отёла
A1: Дата отёла | B1: Прц | C1: Кол-в | D1: Телка | E1: Бычок | M1: Скопируй таблицу и вставь сюда
A2: =M5 -> 46243 | B2: 0 | C2: 0 | D2: =O5 -> 12 | E2: =P5 -> 5
A3: =M6 -> 46244 | D3: =O6 -> 9 | E3: =P6 -> 5
A4: =M7 -> 46245 | D4: =O7 -> 11 | E4: =P7 -> 4 | M4: День | N4: Число отёлов | O4: Родилось тёлок | P4: Родилось быков
A5: =M8 -> 46246 | D5: =O8 -> 5 | E5: =P8 -> 3 | M5: 46243 | N5: 17 | O5: 12 | P5: 5
A6: =M9 -> 46247 | D6: =O9 -> 11 | E6: =P9 -> 2 | M6: 46244 | N6: 14 | O6: 9 | P6: 5
A7: =M10 -> 46248 | D7: =O10 -> 12 | E7: =P10 -> 4 | M7: 46245 | N7: 15 | O7: 11 | P7: 4
A8: =M11 -> 46249 | D8: =O11 -> 3 | E8: =P11 -> 0 | M8: 46246 | N8: 8 | O8: 5 | P8: 3
A9: =M12 | D9: =O12 | E9: =P12 | M9: 46247 | N9: 13 | O9: 11 | P9: 2
M10: 46248 | N10: 16 | O10: 12 | P10: 4
M11: 46249 | N11: 3 | O11: 3 | P11: 0
A13: Р

Sheet Проверка УЗИ
A1: 0 | B1: Процент | C1: Событие | D1: Всего | E1: Пн | F1: Вт | G1: Ср | H1: Чт | I1: Пт | J1: Сб | K1: Вс
A2: Стельные | B2: =IFERROR(D2/D4,0) -> 0.64285714 | C2: СТЕЛ | D2: 252
A3: Холостые | B3: =IFERROR(D3/D4,0) -> 0.35714286 | C3: ЯЛОВ | D3: 140
A4: ИТОГО | C4: ИТОГО | D4: =SUM(D2:D3) -> 392
A7: Дата | B7: 46228

Sheet Выбытие телят до 6 месяцев
A1: Ссылка на отчет в Арке | L1: Дата выбытия | M1: Продажа | N1: Падёж | P1: Сумма
A2: Дата выбытия | B2: Прц | C2: Кол-в | L2: 46237 | M2: 0 | N2: 1 | P2: =M2+N2 -> 1
A3: =A4-1 -> 46218 | B3: 0 | C3: =IFERROR(XLOOKUP(A3,$L$2:$L$21,$P$2:$P$21),0) -> 0 | P3: =M3+N3 -> 0
A4: =A5-1 -> 46219 | B4: 0 | C4: =IFERROR(XLOOKUP(A4,$L$2:$L$21,$P$2:$P$21),0) -> 0 | P4: =M4+N4 -> 0
A5: =A6-1 -> 46220 | B5: 0 | C5: =IFERROR(XLOOKUP(A5,$L$2:$L$21,$P$2:$P$21),0) -> 0 | P5: =M5+N5 -> 0
A6: =A7-1 -> 46221 | B6: 0 | C6: =IFERROR(XLOOKUP(A6,$L$2:$L$21,$P$2:$P$21),0) -> 0 | P6: =M6+N6 -> 0
A7: =A8-1 -> 46222 | B7: 0 | C7: =IFERROR(XLOOKUP(A7,$L$2:$L$21,$P$2:$P$21),0) -> 0 | P7: =M7+N7 -> 0
A8: =A9-1 -> 46223 | B8: 0 | C8: =IFERROR(XLOOKUP(A8,$L$2:$L$21,$P$2:$P$21),0) -> 0 | P8: =M8+N8 -> 0
A9: =A10-1 -> 46224 | B9: 0 | C9: =IFERROR(XLOOKUP(A9,$L$2:$L$21,$P$2:$P$21),0) -> 0 | P9: =M9+N9 -> 0
A10: =A11-1 -> 46225 | B10: 0 | C10: =IFERROR(XLOOKUP(A10,$L$2:$L$21,$P$2:$P$21),0) -> 0 | P10: =M10+N10 -> 0
A11: =A12-1 -> 46226 | B11: 0 | C11: =IFERROR(XLOOKUP(A11,$L$2:$L$21,$P$2:$P$21),0) -> 0 | P11: =M11+N11 -> 0
A12: =A13-1 -> 46227 | B12: 0 | C12: =IFERROR(XLOOKUP(A12,$L$2:$L$21,$P$2:$P$21),0) -> 0 | P12: =M12+N12 -> 0
A13: =A14-1 -> 46228 | B13: 0 | C13: =IFERROR(XLOOKUP(A13,$L$2:$L$21,$P$2:$P$21),0) -> 0 | P13: =M13+N13 -> 0
A14: =A15-1 -> 46229 | B14: 0 | C14: =IFERROR(XLOOKUP(A14,$L$2:$L$21,$P$2:$P$21),0) -> 0 | P14: =M14+N14 -> 0
... A21: =A22-1 -> 46236 | B21: 0 | C21: =IFERROR(XLOOKUP(A21,$L$2:$L$21,$P$2:$P$21),0) -> 0 | P21: =M21+N21 -> 0
A22: =A23-1 -> 46237 | B22: 0 | C22: =IFERROR(XLOOKUP(A22,$L$2:$L$21,$P$2:$P$21),0) -> 1
A23: =A24-1 -> 46238 | B23: 0 | C23: =IFERROR(XLOOKUP(A23,$L$2:$L$21,$P$2:$P$21),0) -> 0
A24: =A25-1 -> 46239 | B24: 0 | C24: =IFERROR(XLOOKUP(A24,$L$2:$L$21,$P$2:$P$21),0) -> 0
A25: =A26-1 -> 46240 | B25: 0 | C25: =IFERROR(XLOOKUP(A25,$L$2:$L$21,$P$2:$P$21),0) -> 0
A26: =A27-1 -> 46241 | B26: 0 | C26: =IFERROR(XLOOKUP(A26,$L$2:$L$21,$P$2:$P$21),0) -> 0
A27: =A28-1 -> 46242 | B27: 0 | C27: =IFERROR(XLOOKUP(A27,$L$2:$L$21,$P$2:$P$21),0) -> 0
A28: =A29-1 -> 46243 | B28: 0 | C28: =IFERROR(XLOOKUP(A28,$L$2:$L$21,$P$2:$P$21),0) -> 0
A29: =A30-1 -> 46244 | B29: 0 | C29: =IFERROR(XLOOKUP(A29,$L$2:$L$21,$P$2:$P$21),0) -> 0
A30: =A31-1 -> 46245 | B30: 0 | C30: =IFERROR(XLOOKUP(A30,$L$2:$L$21,$P$2:$P$21),0) -> 0
A31: =A32-1 -> 46246 | B31: 0 | C31: =IFERROR(XLOOKUP(A31,$L$2:$L$21,$P$2:$P$21),0) -> 0
A32: =A33-1 -> 46247 | B32: 0 | C32: =IFERROR(XLOOKUP(A32,$L$2:$L$21,$P$2:$P$21),0) -> 0
A33: =A34-1 -> 46248 | B33: 0 | C33: =IFERROR(XLOOKUP(A33,$L$2:$L$21,$P$2:$P$21),0) -> 0
A34: 46249 | B34: 0 | C34: =IFERROR(XLOOKUP(A34,$L$2:$L$21,$P$2:$P$21),0) -> 0

Sheet Выбытие до 60 дней  за год
A1: МЕСЯЦ | B1: ОТЕЛ | C1: ВЫБЫТИЕ | D1: СОХРАННОСТЬ | E1: ВЫБЫТИЕ %
A2: =M3 -> сен 2025 | B2: =N3+P3 -> 462 | C2: =O3+Q3 -> 70 | D2: =IFERROR((B2-C2)/B2,0) -> 0.84848485 | E2: =IFERROR(C2/B2,0) -> 0.15151515 | M2: Месяц и год отёла | N2: Отел | O2: Падёж | P2: Аборт | Q2: Продажа
A3: =M4 -> 45931 | B3: =N4+P4 -> 460 | C3: =O4+Q4 -> 46 | D3: =IFERROR((B3-C3)/B3,0) -> 0.9 | E3: =IFERROR(C3/B3,0) -> 0.1 | M3: сен 2025 | N3: 455 | O3: 14 | P3: 7 | Q3: 56
A4: =M5 -> ноя 2025 | B4: =N5+P5 -> 314 | C4: =O5+Q5 -> 37 | D4: =IFERROR((B4-C4)/B4,0) -> 0.88216561 | E4: =IFERROR(C4/B4,0) -> 0.11783439 | M4: 45931 | N4: 454 | O4: 9 | P4: 6 | Q4: 37
A5: =M6 -> 45992 | B5: =N6+P6 -> 477 | C5: =O6+Q6 -> 78 | D5: =IFERROR((B5-C5)/B5,0) -> 0.83647799 | E5: =IFERROR(C5/B5,0) -> 0.16352201 | M5: ноя 2025 | N5: 310 | O5: 8 | P5: 4 | Q5: 29
A6: =M7 -> 46023 | B6: =N7+P7 -> 467 | C6: =O7+Q7 -> 75 | D6: =IFERROR((B6-C6)/B6,0) -> 0.83940043 | E6: =IFERROR(C6/B6,0) -> 0.16059957 | M6: 45992 | N6: 470 | O6: 14 | P6: 7 | Q6: 64
A7: =M8 -> фев 2026 | B7: =N8+P8 -> 446 | C7: =O8+Q8 -> 61 | D7: =IFERROR((B7-C7)/B7,0) -> 0.8632287 | E7: =IFERROR(C7/B7,0) -> 0.1367713 | M7: 46023 | N7: 463 | O7: 10 | P7: 4 | Q7: 65
A8: =M9 -> 46082 | B8: =N9+P9 -> 461 | C8: =O9+Q9 -> 64 | D8: =IFERROR((B8-C8)/B8,0) -> 0.86117137 | E8: =IFERROR(C8/B8,0) -> 0.13882863 | M8: фев 2026 | N8: 444 | O8: 6 | P8: 2 | Q8: 55
A9: =M10 -> 46113 | B9: =N10+P10 -> 317 | C9: =O10+Q10 -> 50 | D9: =IFERROR((B9-C9)/B9,0) -> 0.84227129 | E9: =IFERROR(C9/B9,0) -> 0.15772871 | M9: 46082 | N9: 456 | O9: 12 | P9: 5 | Q9: 52
A10: =M11 -> май 2026 | B10: =N11+P11 -> 434 | C10: =O11+Q11 -> 97 | D10: =IFERROR((B10-C10)/B10,0) -> 0.7764977 | E10: =IFERROR(C10/B10,0) -> 0.2235023 | M10: 46113 | N10: 313 | O10: 11 | P10: 4 | Q10: 39
A11: =M12 -> 46174 | B11: =N12+P12 -> 370 | C11: =O12+Q12 -> 69 | D11: =IFERROR((B11-C11)/B11,0) -> 0.81351351 | E11: =IFERROR(C11/B11,0) -> 0.18648649 | M11: май 2026 | N11: 431 | O11: 21 | P11: 3 | Q11: 76
A12: =M13 -> 46204 | B12: =N13+P13 -> 384 | C12: =O13+Q13 -> 35 | D12: =IFERROR((B12-C12)/B12,0) -> 0.90885417 | E12: =IFERROR(C12/B12,0) -> 0.091145833 | M12: 46174 | N12: 363 | O12: 13 | P12: 7 | Q12: 56
A13: =M14 -> 46235 | B13: =N14+P14 -> 253 | C13: =O14+Q14 -> 13 | D13: =IFERROR((B13-C13)/B13,0) -> 0.9486166 | E13: =IFERROR(C13/B13,0) -> 0.051383399 | M13: 46204 | N13: 380 | O13: 7 | P13: 4 | Q13: 28
A14: ИТОГО | B14: =SUM(B2:B13) -> 4845 | C14: =SUM(C2:C13) -> 695 | D14: =1-(C14/B14) -> 0.85655315 | E14: =C14/B14 -> 0.14344685 | M14: 46235 | N14: 252 | O14: 2 | P14: 1 | Q14: 11
B15: B14 - формула | C15: С14 - формула
A17: Ссылка на отчет в Арке

Sheet Выбытие до 60 дней в доении
A1: Дата выбытия | B1: Прц | C1: Кол-в | E1: Ссылка на отчет в Арке | L1: Дата выбытия | M1: Продажа | N1: Падёж | P1: Сумма
A2: =A3-1 -> 46219 | C2: =IFERROR(XLOOKUP(A2,$L$2:$L$19,$P$2:$P$19),0) -> 0 | L2: 46221 | M2: 2 | N2: 0 | P2: =M2+N2 -> 2
A3: =A4-1 -> 46220 | C3: =IFERROR(XLOOKUP(A3,$L$2:$L$19,$P$2:$P$19),0) -> 0 | L3: 46223 | M3: 3 | N3: 0 | P3: =M3+N3 -> 3
A4: =A5-1 -> 46221 | C4: =IFERROR(XLOOKUP(A4,$L$2:$L$19,$P$2:$P$19),0) -> 2 | L4: 46224 | M4: 3 | N4: 0 | P4: =M4+N4 -> 3
A5: =A6-1 -> 46222 | C5: =IFERROR(XLOOKUP(A5,$L$2:$L$19,$P$2:$P$19),0) -> 0 | L5: 46225 | M5: 2 | N5: 1 | P5: =M5+N5 -> 3
A6: =A7-1 -> 46223 | C6: =IFERROR(XLOOKUP(A6,$L$2:$L$19,$P$2:$P$19),0) -> 3 | L6: 46226 | M6: 2 | N6: 0 | P6: =M6+N6 -> 2
A7: =A8-1 -> 46224 | C7: =IFERROR(XLOOKUP(A7,$L$2:$L$19,$P$2:$P$19),0) -> 3 | L7: 46227 | M7: 1 | N7: 0 | P7: =M7+N7 -> 1
A8: =A9-1 -> 46225 | C8: =IFERROR(XLOOKUP(A8,$L$2:$L$19,$P$2:$P$19),0) -> 3 | L8: 46229 | M8: 1 | N8: 0 | P8: =M8+N8 -> 1
A9: =A10-1 -> 46226 | C9: =IFERROR(XLOOKUP(A9,$L$2:$L$19,$P$2:$P$19),0) -> 2 | L9: 46231 | M9: 4 | N9: 0 | P9: =M9+N9 -> 4
A10: =A11-1 -> 46227 | C10: =IFERROR(XLOOKUP(A10,$L$2:$L$19,$P$2:$P$19),0) -> 1 | L10: 46232 | M10: 3 | N10: 0 | P10: =M10+N10 -> 3
A11: =A12-1 -> 46228 | C11: =IFERROR(XLOOKUP(A11,$L$2:$L$19,$P$2:$P$19),0) -> 0 | L11: 46233 | M11: 3 | N11: 0 | P11: =M11+N11 -> 3
A12: =A13-1 -> 46229 | C12: =IFERROR(XLOOKUP(A12,$L$2:$L$19,$P$2:$P$19),0) -> 1 | L12: 46234 | M12: 2 | N12: 0 | P12: =M12+N12 -> 2
A13: =A14-1 -> 46230 | C13: =IFERROR(XLOOKUP(A13,$L$2:$L$19,$P$2:$P$19),0) -> 0 | L13: 46236 | M13: 0 | N13: 1 | P13: =M13+N13 -> 1
... A17: =A18-1 -> 46234 | C17: =IFERROR(XLOOKUP(A17,$L$2:$L$19,$P$2:$P$19),0) -> 2 | L17: 46243 | M17: 0 | N17: 1 | P17: =M17+N17 -> 1
A18: =A19-1 -> 46235 | C18: {=IFERROR(XLOOKUP(A18,$L$2:$L$38,$P$2:$P$38),0)} -> 0 | L18: 46244 | M18: 4 | N18: 0 | P18: =M18+N18 -> 4
A19: =A20-1 -> 46236 | C19: =IFERROR(XLOOKUP(A19,$L$2:$L$19,$P$2:$P$19),0) -> 1 | L19: 46245 | M19: 1 | N19: 0 | P19: =M19+N19 -> 1
A20: =A21-1 -> 46237 | C20: =IFERROR(XLOOKUP(A20,$L$2:$L$19,$P$2:$P$19),0) -> 0 | L20: 46246 | M20: 5 | N20: 1 | P20: =M20+N20 -> 6
A21: =A22-1 -> 46238 | C21: =IFERROR(XLOOKUP(A21,$L$2:$L$19,$P$2:$P$19),0) -> 1 | L21: 46247 | M21: 3 | N21: 0 | P21: =M21+N21 -> 3
A22: =A23-1 -> 46239 | C22: =IFERROR(XLOOKUP(A23,$L$2:$L$32,$P$2:$P$32),0) -> 5 | L22: 46248 | M22: 3 | N22: 0 | P22: =M22+N22 -> 3
A23: =A24-1 -> 46240 | C23: =IFERROR(XLOOKUP(A24,$L$2:$L$32,$P$2:$P$32),0) -> 0 | P23: =M23+N23 -> 0
A24: =A25-1 -> 46241 | C24: =IFERROR(XLOOKUP(A25,$L$2:$L$32,$P$2:$P$32),0) -> 4 | P24: =M24+N24 -> 0
A25: =A26-1 -> 46242 | C25: =IFERROR(XLOOKUP(A26,$L$2:$L$32,$P$2:$P$32),0) -> 1 | P25: =M25+N25 -> 0
A26: =A27-1 -> 46243 | C26: =IFERROR(XLOOKUP(A27,$L$2:$L$32,$P$2:$P$32),0) -> 4 | P26: =M26+N26 -> 0
A27: =A28-1 -> 46244 | C27: =IFERROR(XLOOKUP(A28,$L$2:$L$32,$P$2:$P$32),0) -> 1 | P27: =M27+N27 -> 0
A28: =A29-1 -> 46245 | C28: =IFERROR(XLOOKUP(A29,$L$2:$L$32,$P$2:$P$32),0) -> 6 | P28: =M28+N28 -> 0
A29: =A30-1 -> 46246 | C29: =IFERROR(XLOOKUP(A30,$L$2:$L$32,$P$2:$P$32),0) -> 3 | P29: =M29+N29 -> 0
A30: =A31-1 -> 46247 | C30: =IFERROR(XLOOKUP(A31,$L$2:$L$32,$P$2:$P$32),0) -> 3 | P30: =M30+N30 -> 0
A31: =A32-1 -> 46248 | C31: =IFERROR(XLOOKUP(A32,$L$2:$L$32,$P$2:$P$32),0) -> 0 | P31: =M31+N31 -> 0
A32: 46249 | C32: =IFERROR(XLOOKUP(A33,$L$2:$L$32,$P$2:$P$32),0) -> 0 | P32: =M32+N32 -> 0
P33: =M33+N33 -> 0
P34: =M34+N34 -> 0
P35: =M35+N35 -> 0
P36: =M36+N36 -> 0
P37: =M37+N37 -> 0
P38: =M38+N38 -> 0

Sheet Отклонения надоя
A1: Дата | B1: Голов | C1: Надой | D1: Отклонение от ср. недельного | E1: Отклонение %
A2: =A3-1 -> 46238 | B2: 3526 | C2: 32.5 | D2: =C2-$C$14 -> 0.43333333 | E2: =D2/$C$14 -> 0.013513514
A3: =A4-1 -> 46239 | B3: 3612 | C3: 32.8 | D3: =C3-$C$14 -> 0.73333333 | E3: =D3/$C$14 -> 0.022869023
A4: =A5-1 -> 46240 | B4: 2188 | C4: 30.8 | D4: =C4-$C$14 -> -1.2666667 | E4: =D4/$C$14 -> -0.03950104
A5: =A6-1 -> 46241 | B5: 3627 | C5: 33.1 | D5: =C5-$C$14 -> 1.0333333 | E5: =D5/$C$14 -> 0.032224532
A6: =A7-1 -> 46242 | B6: 2330 | C6: 31.4 | D6: =C6-$C$14 -> -0.66666667 | E6: =D6/$C$14 -> -0.020790021
A7: =A8-1 -> 46243 | B7: 3610 | C7: 31.5 | D7: =C7-$C$14 -> -0.56666667 | E7: =D7/$C$14 -> -0.017671518
A8: =A9-1 -> 46244 | B8: 3678 | C8: 32 | D8: =C8-$C$14 -> -0.066666667 | E8: =D8/$C$14 -> -0.0020790021
A9: =A10-1 -> 46245 | B9: 3775 | C9: 31.8 | D9: =C9-$C$14 -> -0.26666667 | E9: =D9/$C$14 -> -0.0083160083
A10: =A11-1 -> 46246 | B10: 3760 | C10: 32 | D10: =C10-$C$14 -> -0.066666667 | E10: =D10/$C$14 -> -0.0020790021
A11: =A12-1 -> 46247 | B11: 3747 | C11: 32 | D11: =C11-$C$14 -> -0.066666667 | E11: =D11/$C$14 -> -0.0020790021
A12: =A13-1 -> 46248 | B12: 2683 | C12: 31.6 | D12: =C12-$C$14 -> -0.46666667 | E12: =D12/$C$14 -> -0.014553015
A13: 46249 | B13: 3455 | C13: 33.3 | D13: =C13-$C$14 -> 1.2333333 | E13: =D13/$C$14 -> 0.038461538
B14: Средненедельный надой | C14: =AVERAGEIF($C$2:$C$13,">0") -> 32.066667
A19: Ссылка на отчет в Арке

Sheet Сохранность молодняка
A1: Месяц рождения | B1: Рождено | C1: Живых | D1: %Сохранности
A2: =N4 -> 46082 | B2: 294 | C2: =P4 | D2: =IFERROR(C2/B2,) -> 0 | N2: ММГГ даты рождения | O2: Выбыла Живет
A3: =N5 -> 46113 | B3: 205 | C3: =P5 | D3: =IFERROR(C3/B3,) -> 0 | O3: 0 | P3: 1 | Q3: Итого
A4: =N6 -> 46143 | B4: =Q6 -> 292 | C4: =P6 | D4: =IFERROR(C4/B4,) -> 0 | N4: 46082 | O4: 294 | Q4: 294
A5: =N7 -> 46174 | B5: =Q7 -> 256 | C5: =P7 | D5: =IFERROR(C5/B5,) -> 0 | N5: 46113 | O5: 205 | Q5: 205
A6: =N8 -> 46204 | B6: =Q8 -> 268 | C6: =P8 | D6: =IFERROR(C6/B6,) -> 0 | N6: 46143 | O6: 292 | Q6: 292
A7: =N9 -> 46235 | B7: =Q9 -> 148 | C7: =P9 -> 15 | D7: =IFERROR(C7/B7,) -> 0.10135135 | N7: 46174 | O7: 256 | Q7: 256
A8: ИТОГО | B8: =SUM(B2:B7) -> 1463 | C8: =SUM(C2:C7) -> 15 | D8: =C8/B8 -> 0.010252905 | N8: 46204 | O8: 268 | Q8: 268
B9: B8 - формула | C9: С9 - формула | N9: 46235 | O9: 133 | P9: 15 | Q9: 148
B10: B2-B7 - заполнить | C10: С2-С8 - формула
A13: Ссылка на отчет в Арке

Sheet Дойных коров и валовый надой
B1: Дойных коров | C1: Всего | D1: Валовый надой сутки | F1: Ссылка на отчет в Арке | O1: СПРАВОЧНИК
A2: =N2 -> Август | B2: 3990 | C2: 31 | D2: =C2*B2 -> 123690 | L2: Сегодня: | M2: =TODAY() -> 46251 | N2: =VLOOKUP(MONTH($M$2),O2:P25,2,0) -> Август | O2: 1 | P2: Январь
A3: =N3 -> Сентябрь | B3: 4032 | C3: 32 | D3: =C3*B3 -> 129024 | N3: =VLOOKUP(MONTH($M$2)+1,O2:P25,2,0) -> Сентябрь | O3: 2 | P3: Февраль
A4: =N4 -> Октябрь | B4: 4017 | C4: 31 | D4: =C4*B4 -> 124527 | N4: =VLOOKUP(MONTH($M$2)+2,O2:P25,2,0) -> Октябрь | O4: 3 | P4: Март
A5: =N5 -> Ноябрь | B5: 3989 | C5: 31 | D5: =C5*B5 -> 123659 | N5: =VLOOKUP(MONTH($M$2)+3,O2:P25,2,0) -> Ноябрь | O5: 4 | P5: Апрель
A6: =N6 -> Декабрь | B6: 3886 | C6: 31 | D6: =C6*B6 -> 120466 | N6: =VLOOKUP(MONTH($M$2)+4,O2:P25,2,0) -> Декабрь | O6: 5 | P6: Май
A7: =N7 -> Январь | B7: 3714 | C7: 31 | D7: =C7*B7 -> 115134 | N7: =VLOOKUP(MONTH($M$2)+5,O2:P25,2,0) -> Январь | O7: 6 | P7: Июнь
A8: =N8 -> Февраль | B8: 3634 | C8: 31 | D8: =C8*B8 -> 112654 | N8: =VLOOKUP(MONTH($M$2)+6,O2:P25,2,0) -> Февраль | O8: 7 | P8: Июль
A9: =N9 -> Март | B9: 3315 | C9: 32 | D9: =C9*B9 -> 106080 | N9: =VLOOKUP(MONTH($M$2)+7,O2:P25,2,0) -> Март | O9: 8 | P9: Август
A10: =N10 -> Апрель | B10: 3234 | C10: 32 | D10: =C10*B10 -> 103488 | N10: =VLOOKUP(MONTH($M$2)+8,O2:P25,2,0) -> Апрель | O10: 9 | P10: Сентябрь
A11: =N11 -> Май | B11: 3121 | C11: 32 | D11: =C11*B11 -> 99872 | N11: =VLOOKUP(MONTH($M$2)+9,O2:P25,2,0) -> Май | O11: 10 | P11: Октябрь
A12: =N12 -> Июнь | B12: 2948 | C12: 31 | D12: =C12*B12 -> 91388 | N12: =VLOOKUP(MONTH($M$2)+10,O3:P26,2,0) -> Июнь | O12: 11 | P12: Ноябрь
A13: =N13 -> Июль | B13: 2734 | C13: 33 | D13: =C13*B13 -> 90222 | N13: =VLOOKUP(MONTH($M$2)+11,O2:P25,2,0) -> Июль | O13: 12 | P13: Декабрь
O14: 13 | P14: Январь
O15: 14 | P15: Февраль
O16: 15 | P16: Март
O17: 16 | P17: Апрель
O18: 17 | P18: Май
O19: 18 | P19: Июнь
O20: 19 | P20: Июль
O21: 20 | P21: Август
O22: 21 | P22: Сентябрь
O23: 22 | P23: Октябрь
O24: 23 | P24: Ноябрь
O25: 24 | P25: Декабрь

Sheet PregRate
A1: Дата | B1: PR | C1: HDR
A2: 44603 | B2: 12 | C2: 12
A3: 44624 | B3: 16 | C3: 16
A4: 44645 | B4: 28 | C4: 28
A5: 44666 | B5: 39 | C5: 41
A6: 44687 | B6: 31 | C6: 32
A7: 44708 | B7: 10 | C7: 11
A8: 44729 | B8: 43 | C8: 45
A9: 44750 | B9: 19 | C9: 23
A10: 44771 | B10: 25 | C10: 31
A11: 44792 | B11: 24 | C11: 29
A12: 44813 | B12: 7 | C12: 14
A13: 44834 | B13: 18 | C13: 25
... A19: 44960 | B19: 0 | C19: 26
A20: Всего | B20: 16 | C20: 24
A22: Bredsum\e
A23: Дата | B23: Ох Приг | C23: Охот | D23: HDR | E23: Ст Приг | F23: Стел | G23: PR | H23: Аборты
A24: 44603 | B24: 42 | C24: 5 | D24: 12 | E24: 42 | F24: 5 | G24: 12 | H24: 0
A25: 44624 | B25: 56 | C25: 9 | D25: 16 | E25: 56 | F25: 9 | G25: 16 | H25: 0
A26: 44645 | B26: 58 | C26: 16 | D26: 28 | E26: 58 | F26: 16 | G26: 28 | H26: 0
A27: 44666 | B27: 61 | C27: 25 | D27: 41 | E27: 61 | F27: 24 | G27: 39 | H27: 0
A28: 44687 | B28: 59 | C28: 19 | D28: 32 | E28: 58 | F28: 18 | G28: 31 | H28: 0
A29: 44708 | B29: 80 | C29: 9 | D29: 11 | E29: 80 | F29: 8 | G29: 10 | H29: 0
A30: 44729 | B30: 105 | C30: 47 | D30: 45 | E30: 104 | F30: 45 | G30: 43 | H30: 1
A31: 44750 | B31: 115 | C31: 26 | D31: 23 | E31: 114 | F31: 22 | G31: 19 | H31: 0
A32: 44771 | B32: 164 | C32: 51 | D32: 31 | E32: 163 | F32: 40 | G32: 25 | H32: 1
A33: 44792 | B33: 165 | C33: 48 | D33: 29 | E33: 165 | F33: 39 | G33: 24 | H33: 1
A34: 44813 | B34: 176 | C34: 24 | D34: 14 | E34: 174 | F34: 13 | G34: 7 | H34: 0
A35: 44834 | B35: 212 | C35: 52 | D35: 25 | E35: 209 | F35: 38 | G35: 18 | H35: 0
... A41: 44960 | B41: 204 | C41: 54 | D41: 26 | E41: 0 | F41: 0 | G41: 0 | H41: 0
A42: Всего | B42: 2279 | C42: 554 | D42: 24 | E42: 2233 | F42: 366 | G42: 16 | H42: 4

Sheet CR%
A1: Месяц | B1: %Стел
A2: =EOMONTH(TODAY(),-15)+1 -> 45809 | B2: 0
A3: =EOMONTH(TODAY(),-14)+1 -> 45839 | B3: 0
A4: =EOMONTH(TODAY(),-13)+1 -> 45870 | B4: 100
A5: =EOMONTH(TODAY(),-12)+1 -> 45901 | B5: 100
A6: =EOMONTH(TODAY(),-11)+1 -> 45931 | B6: 97
A7: =EOMONTH(TODAY(),-10)+1 -> 45962 | B7: 100
A8: =EOMONTH(TODAY(),-9)+1 -> 45992 | B8: 97
A9: =EOMONTH(TODAY(),-8)+1 -> 46023 | B9: 92
A10: =EOMONTH(TODAY(),-7)+1 -> 46054 | B10: 82
A11: =EOMONTH(TODAY(),-6)+1 -> 46082 | B11: 68
A12: =EOMONTH(TODAY(),-5)+1 -> 46113 | B12: 68
A13: =EOMONTH(TODAY(),-4)+1 -> 46143 | B13: 47
A14: =EOMONTH(TODAY(),-3)+1 -> 46174 | B14: 36
A17: Bredsum\c

Sheet CR% Week
A1: Дата | B1: %Стел
A2: =A3-7 -> 44646 | B2: 100
A3: =A4-7 -> 44653 | B3: 100
A4: =A5-7 -> 44660 | B4: 100
A5: =A6-7 -> 44667 | B5: 100
A6: =A7-7 -> 44674 | B6: 100
A7: =A8-7 -> 44681 | B7: 100
A8: =A9-7 -> 44688 | B8: 100
A9: =A10-7 -> 44695 | B9: 100
A10: =A11-7 -> 44702 | B10: 100
A11: =A12-7 -> 44709 | B11: 100
A12: =A13-7 -> 44716 | B12: 100
A13: =A14-7 -> 44723 | B13: 100
... A36: =A37-7 -> 44884 | B36: 47
A37: =A38-7 -> 44891 | B37: 42 | C37: ...
A38: =A39-7 -> 44898 | B38: 38 | C38: -7
A39: =A40-7 -> 44905 | B39: 27 | C39: -7
A40: =A41-7 -> 44912 | B40: 42 | C40: -7
A41: 44919 | B41: 0 | C41: последняя закрытая неделя | E41: вставить дату только в ячейку А41
C42: BREDSUM\R
A45: НЕ ВВОДИТЕ ЗНАЧЕНИЯ В СТОЛБЕЦ A, окромя ячейки A41

Sheet CR% по схеме ИО и месяцу
A1: Процент | B1: Всего | C1: Uncoded | D1: ДаблОвсинк | E1: Овсинк | F1: Охота | G1: Ресинк
A2: =EOMONTH(TODAY(),-6)+1 -> 46082 | B2: 69 | C2: 80
A3: =EOMONTH(TODAY(),-5)+1 -> 46113 | B3: 70 | C3: 72 | F3: 68
A4: =EOMONTH(TODAY(),-4)+1 -> 46143 | B4: 48 | C4: 48 | F4: 47
A5: =EOMONTH(TODAY(),-3)+1 -> 46174 | B5: 35 | C5: 25 | F5: 36
A9: BREDSUM\XCO

Sheet CR% по технику и месяцу
A1: Процент | B1: Всего | C1: Другие | D1: Янцон | E1: Сабиров
A2: август | B2: 85 | C2: 88
A3: сентябрь | B3: 69 | C3: 73
A4: октябрь | B4: 71 | C4: 75 | D4: 33 | E4: 17
A5: ноябрь | B5: 48 | C5: 56 | D5: 35 | E5: 35
A6: декабрь | B6: 36 | C6: 25 | D6: 33 | E6: 44
A13: BREDSUM\XCT

Sheet Поголовье и Вал
B1: Поголовье | C1: Всего | D1: Вал | E1: Ссылка на отчет в Арке
A2: ='Дойных коров и валовый надой'!A2 -> Август | B2: 4871 | C2: ='Дойных коров и валовый надой'!C2 -> 31 | D2: ='Дойных коров и валовый надой'!D2 -> 123690
A3: ='Дойных коров и валовый надой'!A3 -> Сентябрь | B3: 5032 | C3: ='Дойных коров и валовый надой'!C3 -> 32 | D3: ='Дойных коров и валовый надой'!D3 -> 129024
A4: ='Дойных коров и валовый надой'!A4 -> Октябрь | B4: 5244 | C4: ='Дойных коров и валовый надой'!C4 -> 31 | D4: ='Дойных коров и валовый надой'!D4 -> 124527
A5: ='Дойных коров и валовый надой'!A5 -> Ноябрь | B5: 5454 | C5: ='Дойных коров и валовый надой'!C5 -> 31 | D5: ='Дойных коров и валовый надой'!D5 -> 123659
A6: ='Дойных коров и валовый надой'!A6 -> Декабрь | B6: 5559 | C6: ='Дойных коров и валовый надой'!C6 -> 31 | D6: ='Дойных коров и валовый надой'!D6 -> 120466
A7: ='Дойных коров и валовый надой'!A7 -> Январь | B7: 5650 | C7: ='Дойных коров и валовый надой'!C7 -> 31 | D7: ='Дойных коров и валовый надой'!D7 -> 115134
A8: ='Дойных коров и валовый надой'!A8 -> Февраль | B8: 5771 | C8: ='Дойных коров и валовый надой'!C8 -> 31 | D8: ='Дойных коров и валовый надой'!D8 -> 112654
A9: ='Дойных коров и валовый надой'!A9 -> Март | B9: 5837 | C9: ='Дойных коров и валовый надой'!C9 -> 32 | D9: ='Дойных коров и валовый надой'!D9 -> 106080
A10: ='Дойных коров и валовый надой'!A10 -> Апрель | B10: 5998 | C10: ='Дойных коров и валовый надой'!C10 -> 32 | D10: ='Дойных коров и валовый надой'!D10 -> 103488
A11: ='Дойных коров и валовый надой'!A11 -> Май | B11: 6119 | C11: ='Дойных коров и валовый надой'!C11 -> 32 | D11: ='Дойных коров и валовый надой'!D11 -> 99872
A12: ='Дойных коров и валовый надой'!A12 -> Июнь | B12: 6242 | C12: ='Дойных коров и валовый надой'!C12 -> 31 | D12: ='Дойных коров и валовый надой'!D12 -> 91388
A13: ='Дойных коров и валовый надой'!A13 -> Июль | B13: 6366 | C13: ='Дойных коров и валовый надой'!C13 -> 33 | D13: ='Дойных коров и валовый надой'!D13 -> 90222

Sheet Прогноз поголовья Delpro
B1: Дойных | C1: Запуск | D1: Фураж
A2: июнь | B2: 631 | C2: 0 | D2: =B2+C2 -> 631
A3: Отел+ | B3: 0 | C3: 0
A4: Запуск+ | B4: 0 | C4: 0
A5: выбрак | B5: =D5 -> 16.406 | D5: =D2*0.026 -> 16.406
A6: июль | B6: 631 | C6: =C2-C3+C4 -> 0 | D6: =C6+B6 -> 631
A7: Отел | B7: 3 | C7: 3
A8: Запуск | B8: 32 | C8: 32
A9: выбрак | B9: =D9 -> 16.406 | D9: =D6*0.026 -> 16.406
A10: август | B10: =B6+B7-B8-B9 -> 585.594 | C10: =C6-C7+C8 -> 29 | D10: =C10+B10 -> 614.594
A11: Отел | B11: 1 | C11: 1
A12: Запуск | B12: 67 | C12: 67
A13: выбрак | B13: =D13 -> 15.979444 | D13: =D10*0.026 -> 15.979444
A14: сентябрь | B14: =B10+B11-B12-B13 -> 503.61456 | C14: =C10-C11+C12 -> 95 | D14: =C14+B14 -> 598.61456
A15: Отел | B15: 46 | C15: 46
A16: Запуск | B16: 39 | C16: 39
A17: выбрак | B17: =D17 -> 15.563978 | D17: =D14*0.026 -> 15.563978
A18: Октябрь | B18: =B14+B15-B16-B17 -> 495.05058 | C18: =C14-C15+C16 -> 88 | D18: =C18+B18 -> 583.05058
A19: Отел | B19: 88 | C19: 88
A20: Запуск | B20: 0 | C20: 0
A21: выбрак | B21: =D21 -> 15.159315 | D21: =D18*0.026 -> 15.159315
A22: Ноябрь | B22: =B18+B19-B20-B21 -> 567.89126 | C22: =C18-C19+C20 -> 0 | D22: =C22+B22 -> 567.89126
A23: Отел | B23: 53 | C23: 53
A24: Запуск | B24: 0 | C24: 0
A25: выбрак | B25: =D25 -> 14.765173 | D25: =D22*0.026 -> 14.765173
A26: Декабрь | B26: =B22+B23-B24-B25 -> 606.12609 | C26: =C22-C23+C24 -> -53 | D26: =C26+B26 -> 553.12609
A27: Отел | B27: 3 | C27: 3
A28: Запуск | B28: 0 | C28: 0
A29: выбрак | B29: =D29 -> 14.381278 | D29: =D26*0.026 -> 14.381278
A30: январь | B30: =B26+B27-B28-B29 -> 594.74481 | C30: =C26-C27+C28 -> -56 | D30: =C30+B30 -> 538.74481
A31: Отел | B31: 0 | C31: 0
A32: Запуск | B32: 0 | C32: 0
A33: выбрак | B33: 19 | D33: 19

Sheet Список пропущеных животных  с И
A1: Номер животного | B1: Дни в доении | C1: № Лактации | D1: Репро-статус | E1: Номер животного | F1: Дни в доении | G1: № Лактации | H1: Репро-статус | J1: Ссылка на отчет в Арке
A2: 117004 | B2: 74 | C2: 1 | D2: Новотельное | E2: 710048 | F2: 84 | G2: 3 | H2: Новотельное
E4: Итого: 2 | J4: Внизу подписать Итого:

Sheet Список пропущеных животных  с У
A1: ИД | B1: ДДНИ | C1: ЛАКТ | D1: РЕПКД | E1: ДПОХ | F1: ИД | G1: ДДНИ | H1: ЛАКТ | I1: РЕПКД | J1: ДПОХ | L1: Ссылка на отчет в Арке
A2: 103496 | B2: 117 | C2: 2 | D2: Осемененная | E2: 43
E4: Итого: 1 | L4: Внизу подписать Итого:

Sheet Список пропущенных на запуск
A1: Номер животного | B1: Дни стельности | C1: Лактация | D1: Статус коровы | E1: Номер Группы | F1: Номер животного | G1: Дни стельности | H1: Лактация | I1: Статус коровы | J1: Номер Группы | K1: Ссылка на отчет в Арке
A2: 103086 | B2: 226 | C2: 1 | D2: Стельная | E2: 334 | F2: 108378 | G2: 226 | H2: 1 | I2: Стельная | J2: 332
A3: 103093 | B3: 225 | C3: 1 | D3: Стельная | E3: 332 | F3: 108482 | G3: 225 | H3: 1 | I3: Стельная | J3: 343
A4: 103110 | B4: 219 | C4: 1 | D4: Стельная | E4: 381 | F4: 108542 | G4: 226 | H4: 1 | I4: Стельная | J4: 344 | M4: Внизу подписать Итого:
A5: 103122 | B5: 218 | C5: 1 | D5: Стельная | E5: 331 | F5: 108601 | G5: 225 | H5: 1 | I5: Стельная | J5: 343
A6: 103316 | B6: 225 | C6: 2 | D6: Стельная | E6: 373 | F6: 108667 | G6: 219 | H6: 1 | I6: Стельная | J6: 373
A7: 103722 | B7: 219 | C7: 2 | D7: Стельная | E7: 374 | F7: 108737 | G7: 226 | H7: 1 | I7: Стельная | J7: 333
A8: 103762 | B8: 218 | C8: 2 | D8: Стельная | E8: 373 | F8: 108765 | G8: 226 | H8: 1 | I8: Стельная | J8: 333
A9: 103777 | B9: 226 | C9: 2 | D9: Стельная | E9: 381 | F9: 108793 | G9: 219 | H9: 1 | I9: Стельная | J9: 334
A10: 103973 | B10: 218 | C10: 2 | D10: Стельная | E10: 374 | F10: 108798 | G10: 219 | H10: 1 | I10: Стельная | J10: 333
A11: 104037 | B11: 218 | C11: 2 | D11: Стельная | E11: 381 | F11: 108824 | G11: 225 | H11: 1 | I11: Стельная | J11: 332
A12: 104044 | B12: 225 | C12: 2 | D12: Стельная | E12: 374 | F12: 108986 | G12: 225 | H12: 1 | I12: Стельная | J12: 332
A13: 104093 | B13: 225 | C13: 2 | D13: Стельная | E13: 381 | F13: 109008 | G13: 218 | H13: 1 | I13: Стельная | J13: 332
A14: 104909 | B14: 219 | C14: 1 | D14: Стельная | E14: 343 | F14: 109016 | G14: 218 | H14: 1 | I14: Стельная | J14: 331
A15: 105590 | B15: 218 | C15: 1 | D15: Стельная | E15: 331 | F15: 190059 | G15: 219 | H15: 4 | I15: Стельная | J15: 381
A16: 105848 | B16: 225 | C16: 1 | D16: Стельная | E16: 334 | F16: 204385 | G16: 219 | H16: 2 | I16: Стельная | J16: 381
... A32: 108237 | B32: 225 | C32: 1 | D32: Стельная | E32: 332 | F32: 967176 | G32: 226 | H32: 3 | I32: Стельная | J32: 374
F34: Итого: 102

Sheet не трогать
A1: название хоз-ва | B1: СП Калужское | C1: с 31/1/22 | D1: по 7/2/22
A2: дата
A3: Отел
A4: План | B4: 15 | C4: 44484 | D4: 44490 | E4: LIST ID %50.pcdat.276.pdue DUE RPRO LACT DCC PDCC FDAT FOR rc<>1 (DUE=15/10/21-21/10/21)(PDUE=15/10/21-21/10/21 PDUE>DUE)
A5: Коров | B5: 11 | E5: SUM BY LGRP FOR RC<>1 (DUE=15/10/21-21/10/21)(%50.pcdat.276.pdue=15/10/21-21/10/21 PDUE>DUE)
A6: Нетелей | B6: 4
A7: Факт отел | B7: 16 | E7: LIST ID PDUE DUE RPRO LACT DCC PDCC FDAT FOR RC<>1 FDAT=15/10/21-21/10/21
A8: коров | B8: 11 | E8: LIST ID PDUE DUE RPRO LACT DCC PDCC FDAT FOR RC<>1 FDAT=15/10/21-21/10/21 lact>1
A9: Нетелей | B9: 5 | E9: LIST ID PDUE DUE RPRO LACT DCC PDCC FDAT FOR RC<>1 FDAT=15/10/21-21/10/21 lact=1
A10: Отел раньше 265 дней | B10: 3 | E10: SUM FOR PDCC<265 FDAT=15/10/21-21/10/21
A11: Отел позже 295 | B11: 0 | E11: SUM FOR PDCC>295 FDAT=15/10/21-21/10/21
A12: Еще не отелилось а должно | B12: 0 | E12: LIST ID PDUE DUE RPRO LACT DCC PDCC FDAT FOR RC<>1 FDAT<DUE (DUE=15/10/21-21/10/21)(PDUE=15/10/21-21/10/21 PDUE>DUE)
A13: Средние дни стельности при отеле | B13: 264 | E13: SUM PDCC FOR FDAT=15/10/21-21/10/21\B
A15: Всего телят | B15: 12
A16: Быков | B16: 6
A17: Телок | B17: 6 | C17: 0.45
A18: Мертвых | B18: 2 | C18: 0.09
A19: % Мертвых Быков | B19: 0.17 | C19: 0.16
A20: % Мертвых Телок | B20: 0 | C20: 0
A21: %Телок | B21: 0.5
A22: Выбытие новотельных до 60 дней за последние 90 дней | F22: МЕСЯЦ ОТЕЛА | G22: ОТЕЛ | H22: ПРОДАЖА | I22: % ВЫБЫТИЯ | J22: %Сохранности | K22: Месяц рождения | L22: Рождено | M22: Живых | N22: %Сохранности | O22: SUM BY BIMON BY ARMON FOR LACT=0 GNDR=F BDAT>-180\B
A23: Отелилось | B23: 191 | E23: GRAPH SOLD DIED FRESH FOR DIM<61\FD90 | F23: ноя21 | G23: 45 | H23: 7 | I23: 0.16 | J23: =(G23-H23)/G23 -> 0.84444444 | K23: янв | L23: 34 | M23: 33 | N23: 0.97
A24: Выбыло до 61 дня | B24: 25 | F24: 44916 | G24: 59 | H24: 8 | I24: 0.14 | J24: =(G24-H24)/G24 -> 0.86440678 | K24: фев | L24: 6 | M24: 6 | N24: 1
A25: % выбытия | B25: 0.13 | F25: 44583 | G25: 66 | H25: 5 | I25: 0.08 | J25: =(G25-H25)/G25 -> 0.92424242 | K25: авг | L25: 33 | M25: 13 | N25: 0.39
F26: фев22 | G26: 12 | H26: 0 | I26: 0 | J26: =(G26-H26)/G26 -> 1 | K26: сен | L26: 13 | M26: 9 | N26: 0.69
A27: Сохранность телок до 6 месяцев | F27: Всего | G27: 182 | H27: 20 | I27: 0.11 | J27: =(G27-H27)/G27 -> 0.89010989 | K27: окт | L27: 26 | M27: 24 | N27: 0.92
A28: Родилось | B28: 264 | E28: SUM BY BIMON BY ARMON FOR BDAT>-180 GNDR=F\B | K28: ноя | L28: 20 | M28: 19 | N28: 0.95
A29: Живет | B29: 133 | K29: дек | L29: 30 | M29: 29 | N29: 0.97
A30: % сохранности | B30: =B29/B28*100 -> 50.378788 | K30: Всего | L30: 162 | M30: 133 | N30: 0.82
A32: Воспроизводство
A33: Дни в доении при первом осеменении | B33: 69 | E33: SUM DIMFB FOR FBDAT=15/10/21-21/10/21 TBRD=1 LACT>0
A34: Осеменились раньше ПДО 72 дня | B34: 0 | E34: SUM DIMFB FOR FBDAT=15/10/21-21/10/21 TBRD=1 LACT>0 DIMFB<72
A35: Осеменились позже | B35: 0 | E35: SUM DIMFB FOR FBDAT=15/10/21-21/10/21 TBRD=1 LACT>0 DIMFB>78
A36: Осеменения отсутствуют дни в доении >96 | B36: 19 | E36: SUM DIMFB FOR DIM>96 LACT>0 TBRD=0 BY RPRO
A37: %до 72 дней в доении | B37: 0.01 | E37: SUM DIMFB=72 DIMFB=79 FOR LACT>0 DIMFB>0\b
A38: % 72-78 | B38: 0.8
A39: %>78 | B39: 0.2
A40: Средний интервал между ИО | B40: 54 | E40: SUM HINT FOR TBRD>1 LACT>0\B
A41: Должны проверить на УЗИ1 | B41: 10 | E41: SUM FOR DSLH=39-45 LACT>0 BY RPRO
A42: По факту проверено | B42: 9
...

Sheet не трогать2
A1: 1-й день | B1: 2-й день | C1: 3-й день
A2: 9:00 Интерфейс программы | B2: 9:00 Создание пунктов коровы | C2: 9:00 Анализ отела и событий команда EVENTS;
A3: 10:45 Общая структура команд программы | B3: 10:45 Настройка меню | C3: 10:45 График событий команда EGRAPH;
A4: 12:00 Обед | B4: 12:00 Обед | C4: 12:00 Обед;
A5: 13:00 Обзор ТМР-трекер - Стюфляев | B5: 13:00 Обзор Идентификации - Макаров | C5: 13:00 Обзор HeaTime - Герасимов
A6: 13:30 Команды LIST/SHOW списки | B6: 13:30 Свободные отчеты команды SUM | C6: 13:30 Графики надоев и контрольные дойки PLOT;
A7: 14:45 Ввод информации, события, списки, контрольные дойки | B7: 14:30 Анализ воспроизводства команда Bredsum | C7: 14:10 Прогноз поголовья, мониторинг стада, выбытие ECON;
A8: 16:30 Меню ALTER настройка групп, техников, таблица отела, событий, вет. протоколов | B8: 16:30 Отчет доильного зала Parlor | C8: 15:10 Загрузка информации и добавление животных GRAPH.
B9: 17:00 CowValue | C9: 16:10 Генетическое планирование
C10: 16:30 Vas Platform HerdMonitor

Sheet не трогать3
A1: Отсутствует информация по предкам
A2: по отцу | B2: 74 | C2: SUM BY SID
A3: по матери | B3: 1416 | C3: SUM BY DID
A4: Отец матери | B4: 5542 | C4: SUM BY MGSID
A6: Взвешивание
A7: Вес при рождении отсутствует | B7: 1360 | C7: SUM BY BWT FOR LACT=0
A8: Отсутствует событие вес | B8: 4 | C8: SUM FOR %70.41=0 lact=0
A9: Таблица привесов | C9: SUM ADG ADGI BY AGE FOR LACT=0 AGE<12
A11: По ВОЗРМ | B11: Прц | C11: Кол-в | D11: Привес | E11: Ср ADGI
A12: 0-0 | B12: 13 | C12: 747 | D12: 0 | E12: 0
A13: 0-1 | B13: 12 | C13: 692 | D13: 0 | E13: 0
A14: 0-2 | B14: 11 | C14: 601 | D14: 0.76 | E14: 0.74
A15: 0-3 | B15: 9 | C15: 497 | D15: 0.87 | E15: 1.17
A16: 0-4 | B16: 11 | C16: 592 | D16: 0.82 | E16: 0.8
A17: 0-5 | B17: 7 | C17: 414 | D17: 0.83 | E17: 1.01
A18: 0-6 | B18: 5 | C18: 296 | D18: 0.81 | E18: 1.04
A19: 0-7 | B19: 6 | C19: 314 | D19: 0.83 | E19: 0.89
A20: 0-8 | B20: 6 | C20: 320 | D20: 0.75 | E20: 0.75
A21: 0-9 | B21: 5 | C21: 261 | D21: 0.76 | E21: 1.46
A22: 0-10 | B22: 6 | C22: 323 | D22: 0.75 | E22: 0.74
A23: 0-11 | B23: 10 | C23: 537 | D23: 0.76 | E23: 0.61
A24: Всего | B24: 100 | C24: 5594 | D24: 0.81 | E24: 0.91
A26: Вакцинация
A27: Контроль вакцинации в первые 100 дней жизни | C27: GRAPH VACC \T100AYP
A28: Зафиксированы случаи диареи | B28: 84 | C28: GRAPH DIARHEA FOR LACT=0\YD7
A29: Из них первичных | B29: 21
A30: Зафиксированы случаи пневмонии | B30: 19 | C30: GRAPH PNEU FOR LACT=0\YD7
A31: из них первичных | B31: 9
A33: Сохранность за 180 дней | C33: SUM BY BIMON BY ARMON FOR BDAT>-180 GNDR=F\B
A35: По МРОЖ | B35: Прц | C35: Кол-в | D35: Живых | E35: август | F35: сентябрь | G35: октябрь | H35: ноябрь | I35: декабрь | J35: Сохранность
A36: июн | B36: 7 | C36: 17 | D36: 16 | E36: 0 | F36: 0 | G36: 0 | H36: 1 | I36: 0 | J36: 0.94
A37: июл | B37: 12 | C37: 31 | D37: 29 | E37: 0 | F37: 1 | G37: 1 | H37: 0 | I37: 0 | J37: 0.94
A38: авг | B38: 15 | C38: 38 | D38: 36 | E38: 1 | F38: 0 | G38: 0 | H38: 0 | I38: 1 | J38: 0.95
A39: сен | B39: 7 | C39: 17 | D39: 16 | E39: 0 | F39: 0 | G39: 1 | H39: 0 | I39: 0 | J39: 0.94
A40: окт | B40: 24 | C40: 61 | D40: 60 | E40: 0 | F40: 0 | G40: 0 | H40: 1 | I40: 0 | J40: 0.98
A41: ноя | B41: 28 | C41: 69 | D41: 68 | E41: 0 | F41: 0 | G41: 0 | H41: 0 | I41: 1 | J41: 0.99
A42: дек | B42: 6 | C42: 16 | D42: 16 | E42: 0 | F42: 0 | G42: 0 | H42: 0 | I42: 0 | J42: 1
A43: Всего | B43: 100 | C43: 249 | D43: 241 | E43: 1 | F43: 1 | G43: 2 | H43: 2 | I43: 2 | J43: 0.97
A47: Причины выбытия молодняка | C47: ECON\E FOR LACT=0 GNDR=F
A48: УВЗ | B48: январь | C48: февраль | D48: март | E48: апрель | F48: май | G48: июнь | H48: июль | I48: август | J48: сентябрь | K48: октябрь | L48: ноябрь | M48: декабрь | N48: Общ
...

Sheet не трогать4
A1: Отсутствует информация по предкам
A2: по отцу | B2: 74 | C2: SUM BY SID
A3: по матери | B3: 1416 | C3: SUM BY DID
A4: Отец матери | B4: 5542 | C4: SUM BY MGSID
A6: Взвешивание
A7: Вес при рождении отсутствует | B7: 1360 | C7: SUM BY BWT FOR LACT=0
A8: Отсутствует событие вес | B8: 4 | C8: SUM FOR %70.41=0 lact=0
A9: Таблица привесов | C9: SUM ADG ADGI BY AGE FOR LACT=0 AGE<12
A11: По ВОЗРМ | B11: Прц | C11: Кол-в | D11: Ср ADG | E11: Ср ADGI
A12: 0-0 | B12: 13 | C12: 747 | D12: 0 | E12: 0
A13: 0-1 | B13: 12 | C13: 692 | D13: 0 | E13: 0
A14: 0-2 | B14: 11 | C14: 601 | D14: 0.76 | E14: 0.74
A15: 0-3 | B15: 9 | C15: 497 | D15: 0.87 | E15: 1.17
A16: 0-4 | B16: 11 | C16: 592 | D16: 0.82 | E16: 0.8
A17: 0-5 | B17: 7 | C17: 414 | D17: 0.83 | E17: 1.01
A18: 0-6 | B18: 5 | C18: 296 | D18: 0.81 | E18: 1.04
A19: 0-7 | B19: 6 | C19: 314 | D19: 0.83 | E19: 0.89
A20: 0-8 | B20: 6 | C20: 320 | D20: 0.75 | E20: 0.75
A21: 0-9 | B21: 5 | C21: 261 | D21: 0.76 | E21: 1.46
A22: 0-10 | B22: 6 | C22: 323 | D22: 0.75 | E22: 0.74
A23: 0-11 | B23: 10 | C23: 537 | D23: 0.76 | E23: 0.61
A24: Всего | B24: 100 | C24: 5594 | D24: 0.81 | E24: 0.91
A26: Вакцинация
A27: Контроль вакцинации в первые 100 дней жизни | C27: GRAPH VACC \T100AYP
A28: Зафиксированы случаи диареи | B28: 84 | C28: GRAPH DIARHEA FOR LACT=0\YD7
A29: Из них первичных | B29: 21
A30: Зафиксированы случаи пневмонии | B30: 19 | C30: GRAPH PNEU FOR LACT=0\YD7
A31: из них первичных | B31: 9
A33: Сохранность за 180 дней от даты рождения | C33: SUM BY BIMON BY ARMON FOR BDAT>-180 GNDR=F\B
A35: По МРОЖ | B35: Прц | C35: Кол-в | D35: ВЫБ=--- | E35: ВЫБ=авг | F35: ВЫБ=сен | G35: ВЫБ=дек | H35: ВЫБ=ноя | I35: ВЫБ=дек | J35: Сохранность
A36: 44368 | B36: 7 | C36: 17 | D36: 16 | E36: 0 | F36: 0 | G36: 0 | H36: 1 | I36: 0 | J36: 0.94
A37: 44398 | B37: 12 | C37: 31 | D37: 29 | E37: 0 | F37: 1 | G37: 0 | H37: 0 | I37: 0 | J37: 0.94
A38: 44429 | B38: 15 | C38: 38 | D38: 36 | E38: 1 | F38: 0 | G38: 1 | H38: 0 | I38: 1 | J38: 0.95
A39: сен21 | B39: 7 | C39: 17 | D39: 16 | E39: 0 | F39: 0 | G39: 0 | H39: 0 | I39: 0 | J39: 0.94
A40: 44490 | B40: 24 | C40: 61 | D40: 60 | E40: 0 | F40: 0 | G40: 0 | H40: 1 | I40: 0 | J40: 0.98
A41: ноя21 | B41: 28 | C41: 69 | D41: 68 | E41: 0 | F41: 0 | G41: 1 | H41: 0 | I41: 1 | J41: 0.99
A42: 44551 | B42: 6 | C42: 16 | D42: 16 | E42: 0 | F42: 0 | G42: 0 | H42: 0 | I42: 0 | J42: 1
A43: Всего | B43: 100 | C43: 249 | D43: 241 | E43: 1 | F43: 1 | G43: 2 | H43: 2 | I43: 2 | J43: 0.97
A45: Сохранность с момента ввода в стадо | C45: SUM by %130.edat by armon for edat>-180\b
A47: By T1025 | B47: Прц | C47: Кол-в | D47: --- | E47: июл | F47: авг | G47: ноя | H47: окт | I47: ноя | J47: дек | K47: %Сохранности
...
