Workbook

Sheet Отчет АРКА
F31: Еженедельный отчет
F32: ARKA
F33: ='Заполняет конвертор НЕ ТРОГАТЬ!'!Z2 -> 0
A40: ЕЖЕНЕДЕЛЬНЫЙ ОТЧЕТ | O40: ='Заполняет конвертор НЕ ТРОГАТЬ!'!Z1 -> 09.08.2026-15.08.2026
A43: ОБЩЕЕ
G46: ='Показатели и Задачи'!B2 -> 4446 | J46: ='Показатели и Задачи'!B3 -> 50 % | N46: ='Показатели и Задачи'!B4 -> 35 % | Q46: ='Показатели и Задачи'!B5 -> 374 | T46: ='Показатели и Задачи'!B6 -> 0
F48: Коров | I48: Стельных | M48: Первотёлок | P48: DNB | S48: Средний надой
A50: ВОСПРОИЗВОДСТВО
G53: ='Показатели и Задачи'!B7 -> 188.7 | K53: ='Показатели и Задачи'!B10 -> 0.35 | P53: ='Показатели и Задачи'!B8 -> 0.57 | U53: ='Показатели и Задачи'!B9 -> 0.2
F55: DIM | J55: CR | O55: HD | T55: PR
A57: ЗДОРОВЬЕ
H60: ='Показатели и Задачи'!B12 -> 0.14344685 | N60: ='Показатели и Задачи'!B13 -> 0.010252905 | T60: ='Показатели и Задачи'!B14 -> 8 %
G62: Выбытие до 60 дня коров | M62: Сохранность телок за год | S62: Брак коров
B70: www.dfsoft.ru | E70: ="+7-800-707-7-305" -> +7-800-707-7-305 | I70: dc305@dc305.ru
A73: ВЫПОЛНЕНИЕ ТЕХНОЛОГИЧЕСКОЙ КАРТЫ
B75: Выполнение технологической карты
B76: ='Показатели и Задачи'!A18 -> Задача | D76: ='Показатели и Задачи'!B18 -> Пн | E76: ='Показатели и Задачи'!C18 -> Вт | F76: ='Показатели и Задачи'!D18 -> Ср | G76: ='Показатели и Задачи'!E18 -> Чт | H76: ='Показатели и Задачи'!F18 -> Пт | I76: ='Показатели и Задачи'!G18 -> Сб | J76: ='Показатели и Задачи'!H18 -> Вс | L76: Запуск по дням стельности | T76: 1-е осеменение
B77: ='Показатели и Задачи'!A19 -> G7G | D77: ='Показатели и Задачи'!B19 -> 0 | E77: ='Показатели и Задачи'!C19 -> 0 | F77: ='Показатели и Задачи'!D19 -> 0 | G77: ='Показатели и Задачи'!E19 -> 0 | H77: ='Показатели и Задачи'!F19 -> 0 | I77: ='Показатели и Задачи'!G19 -> 0 | J77: ='Показатели и Задачи'!H19 -> 0
B78: ='Показатели и Задачи'!A20 -> Ресинх | D78: ='Показатели и Задачи'!B20 -> 0 | E78: ='Показатели и Задачи'!C20 -> 0 | F78: ='Показатели и Задачи'!D20 -> 0 | G78: ='Показатели и Задачи'!E20 -> 0 | H78: ='Показатели и Задачи'!F20 -> 0 | I78: ='Показатели и Задачи'!G20 -> 0 | J78: ='Показатели и Задачи'!H20 -> 0
B79: ='Показатели и Задачи'!A21 -> Аборт | D79: ='Показатели и Задачи'!B21 -> 0 | E79: ='Показатели и Задачи'!C21 -> 0 | F79: ='Показатели и Задачи'!D21 -> 0 | G79: ='Показатели и Задачи'!E21 -> 0 | H79: ='Показатели и Задачи'!F21 -> 0 | I79: ='Показатели и Задачи'!G21 -> 0 | J79: ='Показатели и Задачи'!H21 -> 0
B80: ='Показатели и Задачи'!A22 -> Брак | D80: ='Показатели и Задачи'!B22 -> 0 | E80: ='Показатели и Задачи'!C22 -> 0 | F80: ='Показатели и Задачи'!D22 -> 0 | G80: ='Показатели и Задачи'!E22 -> 0 | H80: ='Показатели и Задачи'!F22 -> 0 | I80: ='Показатели и Задачи'!G22 -> 0 | J80: ='Показатели и Задачи'!H22 -> 0
B81: ='Показатели и Задачи'!A23 -> Нестельная | D81: ='Показатели и Задачи'!B23 -> 0 | E81: ='Показатели и Задачи'!C23 -> 0 | F81: ='Показатели и Задачи'!D23 -> 0 | G81: ='Показатели и Задачи'!E23 -> 0 | H81: ='Показатели и Задачи'!F23 -> 0 | I81: ='Показатели и Задачи'!G23 -> 0 | J81: ='Показатели и Задачи'!H23 -> 0
B82: ='Показатели и Задачи'!A24 -> Отел | D82: ='Показатели и Задачи'!B24 -> 0 | E82: ='Показатели и Задачи'!C24 -> 0 | F82: ='Показатели и Задачи'!D24 -> 0 | G82: ='Показатели и Задачи'!E24 -> 0 | H82: ='Показатели и Задачи'!F24 -> 0 | I82: ='Показатели и Задачи'!G24 -> 0 | J82: ='Показатели и Задачи'!H24 -> 0
B83: ='Показатели и Задачи'!A25 -> Падёж | D83: ='Показатели и Задачи'!B25 -> 0 | E83: ='Показатели и Задачи'!C25 -> 0 | F83: ='Показатели и Задачи'!D25 -> 0 | G83: ='Показатели и Задачи'!E25 -> 0 | H83: ='Показатели и Задачи'!F25 -> 0 | I83: ='Показатели и Задачи'!G25 -> 0 | J83: ='Показатели и Задачи'!H25 -> 0
B84: ='Показатели и Задачи'!A26 -> Стельная | D84: ='Показатели и Задачи'!B26 -> 0 | E84: ='Показатели и Задачи'!C26 -> 0 | F84: ='Показатели и Задачи'!D26 -> 0 | G84: ='Показатели и Задачи'!E26 -> 0 | H84: ='Показатели и Задачи'!F26 -> 0 | I84: ='Показатели и Задачи'!G26 -> 0 | J84: ='Показатели и Задачи'!H26 -> 0
B85: ='Показатели и Задачи'!A27 -> Взвешивание | D85: ='Показатели и Задачи'!B27 -> 0 | E85: ='Показатели и Задачи'!C27 -> 0 | F85: ='Показатели и Задачи'!D27 -> 0 | G85: ='Показатели и Задачи'!E27 -> 0 | H85: ='Показатели и Задачи'!F27 -> 0 | I85: ='Показатели и Задачи'!G27 -> 0 | J85: ='Показатели и Задачи'!H27 -> 0
B86: ='Показатели и Задачи'!A28 -> Забой | D86: ='Показатели и Задачи'!B28 -> 0 | E86: ='Показатели и Задачи'!C28 -> 0 | F86: ='Показатели и Задачи'!D28 -> 0 | G86: ='Показатели и Задачи'!E28 -> 0 | H86: ='Показатели и Задачи'!F28 -> 0 | I86: ='Показатели и Задачи'!G28 -> 0 | J86: ='Показатели и Задачи'!H28 -> 0
B87: ='Показатели и Задачи'!A29 -> Обезроживание | D87: ='Показатели и Задачи'!B29 -> 0 | E87: ='Показатели и Задачи'!C29 -> 0 | F87: ='Показатели и Задачи'!D29 -> 0 | G87: ='Показатели и Задачи'!E29 -> 0 | H87: ='Показатели и Задачи'!F29 -> 0 | I87: ='Показатели и Задачи'!G29 -> 0 | J87: ='Показатели и Задачи'!H29 -> 0
B88: ='Показатели и Задачи'!A30 -> Осеменение | D88: ='Показатели и Задачи'!B30 -> 0 | E88: ='Показатели и Задачи'!C30 -> 0 | F88: ='Показатели и Задачи'!D30 -> 0 | G88: ='Показатели и Задачи'!E30 -> 0 | H88: ='Показатели и Задачи'!F30 -> 0 | I88: ='Показатели и Задачи'!G30 -> 0 | J88: ='Показатели и Задачи'!H30 -> 0
B89: ='Показатели и Задачи'!A31 -> Перебирковка | D89: ='Показатели и Задачи'!B31 -> 0 | E89: ='Показатели и Задачи'!C31 -> 0 | F89: ='Показатели и Задачи'!D31 -> 0 | G89: ='Показатели и Задачи'!E31 -> 0 | H89: ='Показатели и Задачи'!F31 -> 0 | I89: ='Показатели и Задачи'!G31 -> 0 | J89: ='Показатели и Задачи'!H31 -> 0 | L89: Стельность | T89: 2-е осеменение
B90: ='Показатели и Задачи'!A32 -> Перевод | D90: ='Показатели и Задачи'!B32 -> 0 | E90: ='Показатели и Задачи'!C32 -> 0 | F90: ='Показатели и Задачи'!D32 -> 0 | G90: ='Показатели и Задачи'!E32 -> 0 | H90: ='Показатели и Задачи'!F32 -> 0 | I90: ='Показатели и Задачи'!G32 -> 0 | J90: ='Показатели и Задачи'!H32 -> 0
B91: ='Показатели и Задачи'!A33 -> Поздний сухостой | D91: ='Показатели и Задачи'!B33 -> 0 | E91: ='Показатели и Задачи'!C33 -> 0 | F91: ='Показатели и Задачи'!D33 -> 0 | G91: ='Показатели и Задачи'!E33 -> 0 | H91: ='Показатели и Задачи'!F33 -> 0 | I91: ='Показатели и Задачи'!G33 -> 0 | J91: ='Показатели и Задачи'!H33 -> 0
B92: ='Показатели и Задачи'!A34 -> Сухостой | D92: ='Показатели и Задачи'!B34 -> 0 | E92: ='Показатели и Задачи'!C34 -> 0 | F92: ='Показатели и Задачи'!D34 -> 0 | G92: ='Показатели и Задачи'!E34 -> 0 | H92: ='Показатели и Задачи'!F34 -> 0 | I92: ='Показатели и Задачи'!G34 -> 0 | J92: ='Показатели и Задачи'!H34 -> 0
B93: ='Показатели и Задачи'!A35 -> Продажа | D93: ='Показатели и Задачи'!B35 -> 0 | E93: ='Показатели и Задачи'!C35 -> 0 | F93: ='Показатели и Задачи'!D35 -> 0 | G93: ='Показатели и Задачи'!E35 -> 0 | H93: ='Показатели и Задачи'!F35 -> 0 | I93: ='Показатели и Задачи'!G35 -> 0 | J93: ='Показатели и Задачи'!H35 -> 0
B94: ='Показатели и Задачи'!A36 -> Диарея | D94: ='Показатели и Задачи'!B36 -> 0 | E94: ='Показатели и Задачи'!C36 -> 0 | F94: ='Показатели и Задачи'!D36 -> 0 | G94: ='Показатели и Задачи'!E36 -> 0 | H94: ='Показатели и Задачи'!F36 -> 0 | I94: ='Показатели и Задачи'!G36 -> 0 | J94: ='Показатели и Задачи'!H36 -> 0
B95: ='Показатели и Задачи'!A37 -> Кетоз | D95: ='Показатели и Задачи'!B37 -> 0 | E95: ='Показатели и Задачи'!C37 -> 0 | F95: ='Показатели и Задачи'!D37 -> 0 | G95: ='Показатели и Задачи'!E37 -> 0 | H95: ='Показатели и Задачи'!F37 -> 0 | I95: ='Показатели и Задачи'!G37 -> 0 | J95: ='Показатели и Задачи'!H37 -> 0
B96: ='Показатели и Задачи'!A38 -> Мастит | D96: ='Показатели и Задачи'!B38 -> 0 | E96: ='Показатели и Задачи'!C38 -> 0 | F96: ='Показатели и Задачи'!D38 -> 0 | G96: ='Показатели и Задачи'!E38 -> 0 | H96: ='Показатели и Задачи'!F38 -> 0 | I96: ='Показатели и Задачи'!G38 -> 0 | J96: ='Показатели и Задачи'!H38 -> 0
B97: ='Показатели и Задачи'!A39 -> Молочная лихорадка, Парез | D97: ='Показатели и Задачи'!B39 -> 0 | E97: ='Показатели и Задачи'!C39 -> 0 | F97: ='Показатели и Задачи'!D39 -> 0 | G97: ='Показатели и Задачи'!E39 -> 0 | H97: ='Показатели и Задачи'!F39 -> 0 | I97: ='Показатели и Задачи'!G39 -> 0 | J97: ='Показатели и Задачи'!H39 -> 0
B98: ='Показатели и Задачи'!A40 -> Послеродовой парез | D98: ='Показатели и Задачи'!B40 -> 0 | E98: ='Показатели и Задачи'!C40 -> 0 | F98: ='Показатели и Задачи'!D40 -> 0 | G98: ='Показатели и Задачи'!E40 -> 0 | H98: ='Показатели и Задачи'!F40 -> 0 | I98: ='Показатели и Задачи'!G40 -> 0 | J98: ='Показатели и Задачи'!H40 -> 0
B99: ='Показатели и Задачи'!A41 -> Субклинический мастит | D99: ='Показатели и Задачи'!B41 -> 0 | E99: ='Показатели и Задачи'!C41 -> 0 | F99: ='Показатели и Задачи'!D41 -> 0 | G99: ='Показатели и Задачи'!E41 -> 0 | H99: ='Показатели и Задачи'!F41 -> 0 | I99: ='Показатели и Задачи'!G41 -> 0 | J99: ='Показатели и Задачи'!H41 -> 0
...

Sheet Заполняет конвертор НЕ ТРОГАТЬ!
A1: Показатели и Задачи | J1: Задачи за неделю | S1: Выбытие до 60 дней в доении | Y1: Дата | Z1: 09.08.2026-15.08.2026
A2: Кол-во коров в стаде | B2: 4446 | J2: Задача | K2: Пн | L2: Вт | M2: Ср | N2: Чт | O2: Пт | P2: Сб | Q2: Вс | S2: Дата выбытия | T2: Продажа | U2: Падёж | W2: Сумма | Y2: Название Фермы
A3: % Стельных | B3: 50 % | J3: G7G | T3: 1 | W3: =T3+U3 -> 1 | Y3: Дата нач отчета
A4: % Первотелок | B4: 35 % | J4: Ресинх | W4: =T4+U4 -> 0 | Y4: Дату конца очтета
A5: Кол-во БРАК коровы | B5: 374 | J5: Аборт | W5: =T5+U5 -> 0
A6: Средний надой ДЗ | B6: 32 | J6: Брак | W6: =T6+U6 -> 0
A7: Средние дни в доении (без сух.) | B7: 188.7 | J7: Нестельная | W7: =T7+U7 -> 0
A8: % Брака коровы | B8: 8 % | J8: Отел | W8: =T8+U8 -> 0
J9: Падёж | W9: =T9+U9 -> 0
J10: Стельная | W10: =T10+U10 -> 0
J11: Взвешивание | W11: =T11+U11 -> 0
J12: Забой | W12: =T12+U12 -> 0
J13: Обезроживание | W13: =T13+U13 -> 0
J14: Осеменение | W14: =T14+U14 -> 0
J15: Перебирковка | W15: =T15+U15 -> 0
J16: Перевод | W16: =T16+U16 -> 0
J17: Поздний сухостой | W17: =T17+U17 -> 0
J18: Сухостой | W18: =T18+U18 -> 0
J19: Продажа | W19: =T19+U19 -> 0
J20: Диарея | W20: =T20+U20 -> 0
... J28: Итого | W28: =T28+U28 -> 0
A29: Стельность сухостой | H29: 1\2 ИО | W29: =T29+U29 -> 0
A30: День с осеменения | B30: Нестельная | C30: Стельная | E30: День с осеменения | F30: Сухостой | H30: ID | I30: HDAT | J30: DIMFB | L30: ID | M30: HDAT | N30: DIMSB | W30: =T30+U30 -> 0
A31: 1 | E31: 1 | H31: 1 | L31: 1 | W31: =T31+U31 -> 0
I32: 2 | M32: 2 | W32: =T32+U32 -> 0
J33: 3 | N33: 3 | W33: =T33+U33 -> 0
W34: =T34+U34 -> 0
W35: =T35+U35 -> 0
W36: =T36+U36 -> 0
W37: =T37+U37 -> 0
W38: =T38+U38 -> 0
U39: 2 | W39: =T39+U39 -> 2
S41: Отклонения надоя
S42: Дата | T42: Голов | U42: Надой
S43: =S44-1 -> 46237 | T43: 3526 | U43: 32.5
S44: =S45-1 -> 46238 | T44: 3612 | U44: 32.8
S45: =S46-1 -> 46239 | T45: 2188 | U45: 30.8
S46: =S47-1 -> 46240 | T46: 3627 | U46: 33.1
S47: =S48-1 -> 46241 | T47: 2330 | U47: 31.4
S48: =S49-1 -> 46242 | T48: 3610 | U48: 31.5
...

Sheet HDR и PR   
A1: Дата | B1: Пригодные к осемен. | C1: Осемен. | D1: Выявление (HDR) | E1: Пригодные к стельности | F1: Стельные | G1: Стельность (PR) | H1: Оплодотворяемость (CR) | I1: Аборты
D2: Цель 65 % | G2: Цель 25 % | H2: Цель 45 %
A3: 06.08.2025 – 27.08.2025 | B3: 653 | C3: 432 | D3: 0.66 | E3: 642 | F3: 208 | G3: 0.32 | H3: 0.49 | I3: 36
A4: 27.08.2025 – 17.09.2025 | B4: 640 | C4: 415 | D4: 0.65 | E4: 623 | F4: 189 | G4: 0.3 | H4: 0.46 | I4: 21
A5: 17.09.2025 – 08.10.2025 | B5: 694 | C5: 466 | D5: 0.67 | E5: 675 | F5: 193 | G5: 0.29 | H5: 0.41 | I5: 29
A6: 08.10.2025 – 29.10.2025 | B6: 677 | C6: 395 | D6: 0.58 | E6: 661 | F6: 188 | G6: 0.28 | H6: 0.47 | I6: 24
A7: 29.10.2025 – 19.11.2025 | B7: 591 | C7: 404 | D7: 0.68 | E7: 580 | F7: 192 | G7: 0.33 | H7: 0.47 | I7: 21
A8: 19.11.2025 – 10.12.2025 | B8: 639 | C8: 404 | D8: 0.63 | E8: 630 | F8: 174 | G8: 0.28 | H8: 0.44 | I8: 17
A9: 10.12.2025 – 31.12.2025 | B9: 668 | C9: 439 | D9: 0.66 | E9: 661 | F9: 168 | G9: 0.25 | H9: 0.4 | I9: 26
A10: 31.12.2025 – 21.01.2026 | B10: 680 | C10: 383 | D10: 0.56 | E10: 664 | F10: 146 | G10: 0.22 | H10: 0.39 | I10: 23
A11: 21.01.2026 – 11.02.2026 | B11: 647 | C11: 407 | D11: 0.63 | E11: 634 | F11: 149 | G11: 0.24 | H11: 0.38 | I11: 11
A12: 11.02.2026 – 04.03.2026 | B12: 694 | C12: 434 | D12: 0.63 | E12: 682 | F12: 175 | G12: 0.26 | H12: 0.42 | I12: 15
A13: 04.03.2026 – 25.03.2026 | B13: 723 | C13: 463 | D13: 0.64 | E13: 715 | F13: 192 | G13: 0.27 | H13: 0.4 | I13: 6
A14: 25.03.2026 – 15.04.2026 | B14: 761 | C14: 482 | D14: 0.63 | E14: 746 | F14: 165 | G14: 0.22 | H14: 0.35 | I14: 10
... A18: 17.06.2026 – 08.07.2026 | B18: 894 | C18: 512 | D18: 0.57 | E18: 883 | F18: 174 | G18: 0.2 | H18: 0.35 | I18: 0
A19: 08.07.2026 – 29.07.2026 | B19: 859 | C19: 533 | D19: 0.62 | E19: 838 | F19: 132 | H19: 0.39 | I19: 0
A20: 29.07.2026 – 19.08.2026 | B20: 677 | C20: 527 | D20: 0.78 | E20: 673 | F20: 0 | I20: 0

Sheet Показатели и Задачи
A1: Название хозяйства | B1: ='Заполняет конвертор НЕ ТРОГАТЬ!'!Z2 -> 0
A2: Коров | B2: ='Заполняет конвертор НЕ ТРОГАТЬ!'!B2 -> 4446
A3: Стельных | B3: ='Заполняет конвертор НЕ ТРОГАТЬ!'!B3 -> 50 %
A4: Первотелок | B4: ='Заполняет конвертор НЕ ТРОГАТЬ!'!B4 -> 35 %
A5: БРАК | B5: ='Заполняет конвертор НЕ ТРОГАТЬ!'!B5 -> 374
A6: Средний надой | B6: =E5 -> 0
A7: DIM | B7: ='Заполняет конвертор НЕ ТРОГАТЬ!'!B7 -> 188.7
A8: HD | B8: ='HDR и PR '!D18 -> 0.57
A9: PR | B9: ='HDR и PR '!G18 -> 0.2
A10: CR | B10: ='HDR и PR '!H18 -> 0.35
A11: Стельных осем по HT телок | B11: 0
A12: Выбытие до 60 дня коров | B12: =1-'Выбытие до 60 дней за год'!D14 -> 0.14344685
A13: Сохранность за год телят | B13: ='Сохранность молодняка'!D8 -> 0.010252905
A14: Брак коров | B14: ='Заполняет конвертор НЕ ТРОГАТЬ!'!B8 -> 8 %
A15: Что-то еще | B15: 0
A17: Ссылка на отчет в Арке
A18: Задача | B18: Пн | C18: Вт | D18: Ср | E18: Чт | F18: Пт | G18: Сб | H18: Вс
A19: G7G | B19: ='Заполняет конвертор НЕ ТРОГАТЬ!'!K3 -> 0 | C19: ='Заполняет конвертор НЕ ТРОГАТЬ!'!L3 -> 0 | D19: ='Заполняет конвертор НЕ ТРОГАТЬ!'!M3 -> 0 | E19: ='Заполняет конвертор НЕ ТРОГАТЬ!'!N3 -> 0 | F19: ='Заполняет конвертор НЕ ТРОГАТЬ!'!O3 -> 0 | G19: ='Заполняет конвертор НЕ ТРОГАТЬ!'!P3 -> 0 | H19: ='Заполняет конвертор НЕ ТРОГАТЬ!'!Q3 -> 0
A20: Ресинх | B20: ='Заполняет конвертор НЕ ТРОГАТЬ!'!K4 -> 0 | C20: ='Заполняет конвертор НЕ ТРОГАТЬ!'!L4 -> 0 | D20: ='Заполняет конвертор НЕ ТРОГАТЬ!'!M4 -> 0 | E20: ='Заполняет конвертор НЕ ТРОГАТЬ!'!N4 -> 0 | F20: ='Заполняет конвертор НЕ ТРОГАТЬ!'!O4 -> 0 | G20: ='Заполняет конвертор НЕ ТРОГАТЬ!'!P4 -> 0 | H20: ='Заполняет конвертор НЕ ТРОГАТЬ!'!Q4 -> 0
A21: Аборт | B21: ='Заполняет конвертор НЕ ТРОГАТЬ!'!K5 -> 0 | C21: ='Заполняет конвертор НЕ ТРОГАТЬ!'!L5 -> 0 | D21: ='Заполняет конвертор НЕ ТРОГАТЬ!'!M5 -> 0 | E21: ='Заполняет конвертор НЕ ТРОГАТЬ!'!N5 -> 0 | F21: ='Заполняет конвертор НЕ ТРОГАТЬ!'!O5 -> 0 | G21: ='Заполняет конвертор НЕ ТРОГАТЬ!'!P5 -> 0 | H21: ='Заполняет конвертор НЕ ТРОГАТЬ!'!Q5 -> 0
A22: Брак | B22: ='Заполняет конвертор НЕ ТРОГАТЬ!'!K6 -> 0 | C22: ='Заполняет конвертор НЕ ТРОГАТЬ!'!L6 -> 0 | D22: ='Заполняет конвертор НЕ ТРОГАТЬ!'!M6 -> 0 | E22: ='Заполняет конвертор НЕ ТРОГАТЬ!'!N6 -> 0 | F22: ='Заполняет конвертор НЕ ТРОГАТЬ!'!O6 -> 0 | G22: ='Заполняет конвертор НЕ ТРОГАТЬ!'!P6 -> 0 | H22: ='Заполняет конвертор НЕ ТРОГАТЬ!'!Q6 -> 0
A23: Нестельная | B23: ='Заполняет конвертор НЕ ТРОГАТЬ!'!K7 -> 0 | C23: ='Заполняет конвертор НЕ ТРОГАТЬ!'!L7 -> 0 | D23: ='Заполняет конвертор НЕ ТРОГАТЬ!'!M7 -> 0 | E23: ='Заполняет конвертор НЕ ТРОГАТЬ!'!N7 -> 0 | F23: ='Заполняет конвертор НЕ ТРОГАТЬ!'!O7 -> 0 | G23: ='Заполняет конвертор НЕ ТРОГАТЬ!'!P7 -> 0 | H23: ='Заполняет конвертор НЕ ТРОГАТЬ!'!Q7 -> 0
A24: Отел | B24: ='Заполняет конвертор НЕ ТРОГАТЬ!'!K8 -> 0 | C24: ='Заполняет конвертор НЕ ТРОГАТЬ!'!L8 -> 0 | D24: ='Заполняет конвертор НЕ ТРОГАТЬ!'!M8 -> 0 | E24: ='Заполняет конвертор НЕ ТРОГАТЬ!'!N8 -> 0 | F24: ='Заполняет конвертор НЕ ТРОГАТЬ!'!O8 -> 0 | G24: ='Заполняет конвертор НЕ ТРОГАТЬ!'!P8 -> 0 | H24: ='Заполняет конвертор НЕ ТРОГАТЬ!'!Q8 -> 0
A25: Падёж | B25: ='Заполняет конвертор НЕ ТРОГАТЬ!'!K9 -> 0 | C25: ='Заполняет конвертор НЕ ТРОГАТЬ!'!L9 -> 0 | D25: ='Заполняет конвертор НЕ ТРОГАТЬ!'!M9 -> 0 | E25: ='Заполняет конвертор НЕ ТРОГАТЬ!'!N9 -> 0 | F25: ='Заполняет конвертор НЕ ТРОГАТЬ!'!O9 -> 0 | G25: ='Заполняет конвертор НЕ ТРОГАТЬ!'!P9 -> 0 | H25: ='Заполняет конвертор НЕ ТРОГАТЬ!'!Q9 -> 0
A26: Стельная | B26: ='Заполняет конвертор НЕ ТРОГАТЬ!'!K10 -> 0 | C26: ='Заполняет конвертор НЕ ТРОГАТЬ!'!L10 -> 0 | D26: ='Заполняет конвертор НЕ ТРОГАТЬ!'!M10 -> 0 | E26: ='Заполняет конвертор НЕ ТРОГАТЬ!'!N10 -> 0 | F26: ='Заполняет конвертор НЕ ТРОГАТЬ!'!O10 -> 0 | G26: ='Заполняет конвертор НЕ ТРОГАТЬ!'!P10 -> 0 | H26: ='Заполняет конвертор НЕ ТРОГАТЬ!'!Q10 -> 0
A27: Взвешивание | B27: ='Заполняет конвертор НЕ ТРОГАТЬ!'!K11 -> 0 | C27: ='Заполняет конвертор НЕ ТРОГАТЬ!'!L11 -> 0 | D27: ='Заполняет конвертор НЕ ТРОГАТЬ!'!M11 -> 0 | E27: ='Заполняет конвертор НЕ ТРОГАТЬ!'!N11 -> 0 | F27: ='Заполняет конвертор НЕ ТРОГАТЬ!'!O11 -> 0 | G27: ='Заполняет конвертор НЕ ТРОГАТЬ!'!P11 -> 0 | H27: ='Заполняет конвертор НЕ ТРОГАТЬ!'!Q11 -> 0
A28: Забой | B28: ='Заполняет конвертор НЕ ТРОГАТЬ!'!K12 -> 0 | C28: ='Заполняет конвертор НЕ ТРОГАТЬ!'!L12 -> 0 | D28: ='Заполняет конвертор НЕ ТРОГАТЬ!'!M12 -> 0 | E28: ='Заполняет конвертор НЕ ТРОГАТЬ!'!N12 -> 0 | F28: ='Заполняет конвертор НЕ ТРОГАТЬ!'!O12 -> 0 | G28: ='Заполняет конвертор НЕ ТРОГАТЬ!'!P12 -> 0 | H28: ='Заполняет конвертор НЕ ТРОГАТЬ!'!Q12 -> 0
A29: Обезроживание | B29: ='Заполняет конвертор НЕ ТРОГАТЬ!'!K13 -> 0 | C29: ='Заполняет конвертор НЕ ТРОГАТЬ!'!L13 -> 0 | D29: ='Заполняет конвертор НЕ ТРОГАТЬ!'!M13 -> 0 | E29: ='Заполняет конвертор НЕ ТРОГАТЬ!'!N13 -> 0 | F29: ='Заполняет конвертор НЕ ТРОГАТЬ!'!O13 -> 0 | G29: ='Заполняет конвертор НЕ ТРОГАТЬ!'!P13 -> 0 | H29: ='Заполняет конвертор НЕ ТРОГАТЬ!'!Q13 -> 0
A30: Осеменение | B30: ='Заполняет конвертор НЕ ТРОГАТЬ!'!K14 -> 0 | C30: ='Заполняет конвертор НЕ ТРОГАТЬ!'!L14 -> 0 | D30: ='Заполняет конвертор НЕ ТРОГАТЬ!'!M14 -> 0 | E30: ='Заполняет конвертор НЕ ТРОГАТЬ!'!N14 -> 0 | F30: ='Заполняет конвертор НЕ ТРОГАТЬ!'!O14 -> 0 | G30: ='Заполняет конвертор НЕ ТРОГАТЬ!'!P14 -> 0 | H30: ='Заполняет конвертор НЕ ТРОГАТЬ!'!Q14 -> 0
... A43: Эндометрит | B43: ='Заполняет конвертор НЕ ТРОГАТЬ!'!K27 -> 0 | C43: ='Заполняет конвертор НЕ ТРОГАТЬ!'!L27 -> 0 | D43: ='Заполняет конвертор НЕ ТРОГАТЬ!'!M27 -> 0 | E43: ='Заполняет конвертор НЕ ТРОГАТЬ!'!N27 -> 0 | F43: ='Заполняет конвертор НЕ ТРОГАТЬ!'!O27 -> 0 | G43: ='Заполняет конвертор НЕ ТРОГАТЬ!'!P27 -> 0 | H43: ='Заполняет конвертор НЕ ТРОГАТЬ!'!Q27 -> 0
A44: Итого | B44: =SUM(B19:B43) -> 0 | C44: =SUM(C19:C43) -> 0 | D44: =SUM(D19:D43) -> 0 | E44: =SUM(E19:E43) -> 0 | F44: =SUM(F19:F43) -> 0 | G44: =SUM(G19:G43) -> 0 | H44: =SUM(H19:H43) -> 0

Sheet Стельность сухостой
A2: Стельность | B2: Ссылка на отчет в Арке
A3: День с осеменения | B3: Нестельная | C3: Стельная
A4: =IF('Заполняет конвертор НЕ ТРОГАТЬ!'!A31="", "", 'Заполняет конвертор НЕ ТРОГАТЬ!'!A31) -> 1 | B4: =IF('Заполняет конвертор НЕ ТРОГАТЬ!'!B31="", "", 'Заполняет конвертор НЕ ТРОГАТЬ!'!B31) | C4: =IF('Заполняет конвертор НЕ ТРОГАТЬ!'!C31="", "", 'Заполняет конвертор НЕ ТРОГАТЬ!'!C31)
A5: =IF('Заполняет конвертор НЕ ТРОГАТЬ!'!A32="", "", 'Заполняет конвертор НЕ ТРОГАТЬ!'!A32) | B5: =IF('Заполняет конвертор НЕ ТРОГАТЬ!'!B32="", "", 'Заполняет конвертор НЕ ТРОГАТЬ!'!B32) | C5: =IF('Заполняет конвертор НЕ ТРОГАТЬ!'!C32="", "", 'Заполняет конвертор НЕ ТРОГАТЬ!'!C32)
A6: =IF('Заполняет конвертор НЕ ТРОГАТЬ!'!A33="", "", 'Заполняет конвертор НЕ ТРОГАТЬ!'!A33) | B6: =IF('Заполняет конвертор НЕ ТРОГАТЬ!'!B33="", "", 'Заполняет конвертор НЕ ТРОГАТЬ!'!B33) | C6: =IF('Заполняет конвертор НЕ ТРОГАТЬ!'!C33="", "", 'Заполняет конвертор НЕ ТРОГАТЬ!'!C33)
A7: =IF('Заполняет конвертор НЕ ТРОГАТЬ!'!A34="", "", 'Заполняет конвертор НЕ ТРОГАТЬ!'!A34) | B7: =IF('Заполняет конвертор НЕ ТРОГАТЬ!'!B34="", "", 'Заполняет конвертор НЕ ТРОГАТЬ!'!B34) | C7: =IF('Заполняет конвертор НЕ ТРОГАТЬ!'!C34="", "", 'Заполняет конвертор НЕ ТРОГАТЬ!'!C34)
A8: =IF('Заполняет конвертор НЕ ТРОГАТЬ!'!A35="", "", 'Заполняет конвертор НЕ ТРОГАТЬ!'!A35) | B8: =IF('Заполняет конвертор НЕ ТРОГАТЬ!'!B35="", "", 'Заполняет конвертор НЕ ТРОГАТЬ!'!B35) | C8: =IF('Заполняет конвертор НЕ ТРОГАТЬ!'!C35="", "", 'Заполняет конвертор НЕ ТРОГАТЬ!'!C35)
A9: =IF('Заполняет конвертор НЕ ТРОГАТЬ!'!A36="", "", 'Заполняет конвертор НЕ ТРОГАТЬ!'!A36) | B9: =IF('Заполняет конвертор НЕ ТРОГАТЬ!'!B36="", "", 'Заполняет конвертор НЕ ТРОГАТЬ!'!B36) | C9: =IF('Заполняет конвертор НЕ ТРОГАТЬ!'!C36="", "", 'Заполняет конвертор НЕ ТРОГАТЬ!'!C36)
A10: =IF('Заполняет конвертор НЕ ТРОГАТЬ!'!A37="", "", 'Заполняет конвертор НЕ ТРОГАТЬ!'!A37) | B10: =IF('Заполняет конвертор НЕ ТРОГАТЬ!'!B37="", "", 'Заполняет конвертор НЕ ТРОГАТЬ!'!B37) | C10: =IF('Заполняет конвертор НЕ ТРОГАТЬ!'!C37="", "", 'Заполняет конвертор НЕ ТРОГАТЬ!'!C37)
A11: =IF('Заполняет конвертор НЕ ТРОГАТЬ!'!A38="", "", 'Заполняет конвертор НЕ ТРОГАТЬ!'!A38) | B11: =IF('Заполняет конвертор НЕ ТРОГАТЬ!'!B38="", "", 'Заполняет конвертор НЕ ТРОГАТЬ!'!B38) | C11: =IF('Заполняет конвертор НЕ ТРОГАТЬ!'!C38="", "", 'Заполняет конвертор НЕ ТРОГАТЬ!'!C38)
A12: =IF('Заполняет конвертор НЕ ТРОГАТЬ!'!A39="", "", 'Заполняет конвертор НЕ ТРОГАТЬ!'!A39) | B12: =IF('Заполняет конвертор НЕ ТРОГАТЬ!'!B39="", "", 'Заполняет конвертор НЕ ТРОГАТЬ!'!B39) | C12: =IF('Заполняет конвертор НЕ ТРОГАТЬ!'!C39="", "", 'Заполняет конвертор НЕ ТРОГАТЬ!'!C39)
A13: =IF('Заполняет конвертор НЕ ТРОГАТЬ!'!A40="", "", 'Заполняет конвертор НЕ ТРОГАТЬ!'!A40) | B13: =IF('Заполняет конвертор НЕ ТРОГАТЬ!'!B40="", "", 'Заполняет конвертор НЕ ТРОГАТЬ!'!B40) | C13: =IF('Заполняет конвертор НЕ ТРОГАТЬ!'!C40="", "", 'Заполняет конвертор НЕ ТРОГАТЬ!'!C40)
A14: =IF('Заполняет конвертор НЕ ТРОГАТЬ!'!A41="", "", 'Заполняет конвертор НЕ ТРОГАТЬ!'!A41) | B14: =IF('Заполняет конвертор НЕ ТРОГАТЬ!'!B41="", "", 'Заполняет конвертор НЕ ТРОГАТЬ!'!B41) | C14: =IF('Заполняет конвертор НЕ ТРОГАТЬ!'!C41="", "", 'Заполняет конвертор НЕ ТРОГАТЬ!'!C41)
A15: =IF('Заполняет конвертор НЕ ТРОГАТЬ!'!A42="", "", 'Заполняет конвертор НЕ ТРОГАТЬ!'!A42) | B15: =IF('Заполняет конвертор НЕ ТРОГАТЬ!'!B42="", "", 'Заполняет конвертор НЕ ТРОГАТЬ!'!B42) | C15: =IF('Заполняет конвертор НЕ ТРОГАТЬ!'!C42="", "", 'Заполняет конвертор НЕ ТРОГАТЬ!'!C42)
... A33: =IF('Заполняет конвертор НЕ ТРОГАТЬ!'!A60="", "", 'Заполняет конвертор НЕ ТРОГАТЬ!'!A60) | B33: =IF('Заполняет конвертор НЕ ТРОГАТЬ!'!B60="", "", 'Заполняет конвертор НЕ ТРОГАТЬ!'!B60) -> 1 | C33: =IF('Заполняет конвертор НЕ ТРОГАТЬ!'!C60="", "", 'Заполняет конвертор НЕ ТРОГАТЬ!'!C60) -> 1
A34: День с осеменения | B34: Сухостой | D34: Ссылка на отчет в Арке
A35: =IF('Заполняет конвертор НЕ ТРОГАТЬ!'!E31="", "", 'Заполняет конвертор НЕ ТРОГАТЬ!'!E31) -> 1 | B35: =IF('Заполняет конвертор НЕ ТРОГАТЬ!'!F31="", "", 'Заполняет конвертор НЕ ТРОГАТЬ!'!F31)
A36: =IF('Заполняет конвертор НЕ ТРОГАТЬ!'!E32="", "", 'Заполняет конвертор НЕ ТРОГАТЬ!'!E32) | B36: =IF('Заполняет конвертор НЕ ТРОГАТЬ!'!F32="", "", 'Заполняет конвертор НЕ ТРОГАТЬ!'!F32)
A37: =IF('Заполняет конвертор НЕ ТРОГАТЬ!'!E33="", "", 'Заполняет конвертор НЕ ТРОГАТЬ!'!E33) | B37: =IF('Заполняет конвертор НЕ ТРОГАТЬ!'!F33="", "", 'Заполняет конвертор НЕ ТРОГАТЬ!'!F33)
A38: =IF('Заполняет конвертор НЕ ТРОГАТЬ!'!E34="", "", 'Заполняет конвертор НЕ ТРОГАТЬ!'!E34) | B38: =IF('Заполняет конвертор НЕ ТРОГАТЬ!'!F34="", "", 'Заполняет конвертор НЕ ТРОГАТЬ!'!F34)
A39: =IF('Заполняет конвертор НЕ ТРОГАТЬ!'!E35="", "", 'Заполняет конвертор НЕ ТРОГАТЬ!'!E35) | B39: =IF('Заполняет конвертор НЕ ТРОГАТЬ!'!F35="", "", 'Заполняет конвертор НЕ ТРОГАТЬ!'!F35)
A40: =IF('Заполняет конвертор НЕ ТРОГАТЬ!'!E36="", "", 'Заполняет конвертор НЕ ТРОГАТЬ!'!E36) | B40: =IF('Заполняет конвертор НЕ ТРОГАТЬ!'!F36="", "", 'Заполняет конвертор НЕ ТРОГАТЬ!'!F36)
A41: =IF('Заполняет конвертор НЕ ТРОГАТЬ!'!E37="", "", 'Заполняет конвертор НЕ ТРОГАТЬ!'!E37) | B41: =IF('Заполняет конвертор НЕ ТРОГАТЬ!'!F37="", "", 'Заполняет конвертор НЕ ТРОГАТЬ!'!F37)
A42: =IF('Заполняет конвертор НЕ ТРОГАТЬ!'!E38="", "", 'Заполняет конвертор НЕ ТРОГАТЬ!'!E38) | B42: =IF('Заполняет конвертор НЕ ТРОГАТЬ!'!F38="", "", 'Заполняет конвертор НЕ ТРОГАТЬ!'!F38)
A43: =IF('Заполняет конвертор НЕ ТРОГАТЬ!'!E39="", "", 'Заполняет конвертор НЕ ТРОГАТЬ!'!E39) | B43: =IF('Заполняет конвертор НЕ ТРОГАТЬ!'!F39="", "", 'Заполняет конвертор НЕ ТРОГАТЬ!'!F39)
A44: =IF('Заполняет конвертор НЕ ТРОГАТЬ!'!E40="", "", 'Заполняет конвертор НЕ ТРОГАТЬ!'!E40) | B44: =IF('Заполняет конвертор НЕ ТРОГАТЬ!'!F40="", "", 'Заполняет конвертор НЕ ТРОГАТЬ!'!F40)
A45: =IF('Заполняет конвертор НЕ ТРОГАТЬ!'!E41="", "", 'Заполняет конвертор НЕ ТРОГАТЬ!'!E41) | B45: =IF('Заполняет конвертор НЕ ТРОГАТЬ!'!F41="", "", 'Заполняет конвертор НЕ ТРОГАТЬ!'!F41)
A46: =IF('Заполняет конвертор НЕ ТРОГАТЬ!'!E42="", "", 'Заполняет конвертор НЕ ТРОГАТЬ!'!E42) | B46: =IF('Заполняет конвертор НЕ ТРОГАТЬ!'!F42="", "", 'Заполняет конвертор НЕ ТРОГАТЬ!'!F42)
... A78: =IF('Заполняет конвертор НЕ ТРОГАТЬ!'!E74="", "", 'Заполняет конвертор НЕ ТРОГАТЬ!'!E74) | B78: =IF('Заполняет конвертор НЕ ТРОГАТЬ!'!F74="", "", 'Заполняет конвертор НЕ ТРОГАТЬ!'!F74) -> 1

Sheet 1-е ИО
A1: ID | B1: HDAT | C1: DIMFB | D1: Ссылка на отчет в Арке
A2: =IF('Заполняет конвертор НЕ ТРОГАТЬ!'!H31="", "", 'Заполняет конвертор НЕ ТРОГАТЬ!'!H31) -> 1 | B2: =IF('Заполняет конвертор НЕ ТРОГАТЬ!'!I31="", "", 'Заполняет конвертор НЕ ТРОГАТЬ!'!I31) | C2: =IF('Заполняет конвертор НЕ ТРОГАТЬ!'!J31="", "", 'Заполняет конвертор НЕ ТРОГАТЬ!'!J31)
A3: =IF('Заполняет конвертор НЕ ТРОГАТЬ!'!H32="", "", 'Заполняет конвертор НЕ ТРОГАТЬ!'!H32) | B3: =IF('Заполняет конвертор НЕ ТРОГАТЬ!'!I32="", "", 'Заполняет конвертор НЕ ТРОГАТЬ!'!I32) -> 2 | C3: =IF('Заполняет конвертор НЕ ТРОГАТЬ!'!J32="", "", 'Заполняет конвертор НЕ ТРОГАТЬ!'!J32)
A4: =IF('Заполняет конвертор НЕ ТРОГАТЬ!'!H33="", "", 'Заполняет конвертор НЕ ТРОГАТЬ!'!H33) | B4: =IF('Заполняет конвертор НЕ ТРОГАТЬ!'!I33="", "", 'Заполняет конвертор НЕ ТРОГАТЬ!'!I33) | C4: =IF('Заполняет конвертор НЕ ТРОГАТЬ!'!J33="", "", 'Заполняет конвертор НЕ ТРОГАТЬ!'!J33) -> 3
A5: =IF('Заполняет конвертор НЕ ТРОГАТЬ!'!H34="", "", 'Заполняет конвертор НЕ ТРОГАТЬ!'!H34) | B5: =IF('Заполняет конвертор НЕ ТРОГАТЬ!'!I34="", "", 'Заполняет конвертор НЕ ТРОГАТЬ!'!I34) | C5: =IF('Заполняет конвертор НЕ ТРОГАТЬ!'!J34="", "", 'Заполняет конвертор НЕ ТРОГАТЬ!'!J34)
A6: =IF('Заполняет конвертор НЕ ТРОГАТЬ!'!H35="", "", 'Заполняет конвертор НЕ ТРОГАТЬ!'!H35) | B6: =IF('Заполняет конвертор НЕ ТРОГАТЬ!'!I35="", "", 'Заполняет конвертор НЕ ТРОГАТЬ!'!I35) | C6: =IF('Заполняет конвертор НЕ ТРОГАТЬ!'!J35="", "", 'Заполняет конвертор НЕ ТРОГАТЬ!'!J35)
A7: =IF('Заполняет конвертор НЕ ТРОГАТЬ!'!H36="", "", 'Заполняет конвертор НЕ ТРОГАТЬ!'!H36) | B7: =IF('Заполняет конвертор НЕ ТРОГАТЬ!'!I36="", "", 'Заполняет конвертор НЕ ТРОГАТЬ!'!I36) | C7: =IF('Заполняет конвертор НЕ ТРОГАТЬ!'!J36="", "", 'Заполняет конвертор НЕ ТРОГАТЬ!'!J36)
A8: =IF('Заполняет конвертор НЕ ТРОГАТЬ!'!H37="", "", 'Заполняет конвертор НЕ ТРОГАТЬ!'!H37) | B8: =IF('Заполняет конвертор НЕ ТРОГАТЬ!'!I37="", "", 'Заполняет конвертор НЕ ТРОГАТЬ!'!I37) | C8: =IF('Заполняет конвертор НЕ ТРОГАТЬ!'!J37="", "", 'Заполняет конвертор НЕ ТРОГАТЬ!'!J37)
A9: =IF('Заполняет конвертор НЕ ТРОГАТЬ!'!H38="", "", 'Заполняет конвертор НЕ ТРОГАТЬ!'!H38) | B9: =IF('Заполняет конвертор НЕ ТРОГАТЬ!'!I38="", "", 'Заполняет конвертор НЕ ТРОГАТЬ!'!I38) | C9: =IF('Заполняет конвертор НЕ ТРОГАТЬ!'!J38="", "", 'Заполняет конвертор НЕ ТРОГАТЬ!'!J38)
A10: =IF('Заполняет конвертор НЕ ТРОГАТЬ!'!H39="", "", 'Заполняет конвертор НЕ ТРОГАТЬ!'!H39) | B10: =IF('Заполняет конвертор НЕ ТРОГАТЬ!'!I39="", "", 'Заполняет конвертор НЕ ТРОГАТЬ!'!I39) | C10: =IF('Заполняет конвертор НЕ ТРОГАТЬ!'!J39="", "", 'Заполняет конвертор НЕ ТРОГАТЬ!'!J39)
A11: =IF('Заполняет конвертор НЕ ТРОГАТЬ!'!H40="", "", 'Заполняет конвертор НЕ ТРОГАТЬ!'!H40) | B11: =IF('Заполняет конвертор НЕ ТРОГАТЬ!'!I40="", "", 'Заполняет конвертор НЕ ТРОГАТЬ!'!I40) | C11: =IF('Заполняет конвертор НЕ ТРОГАТЬ!'!J40="", "", 'Заполняет конвертор НЕ ТРОГАТЬ!'!J40)
A12: =IF('Заполняет конвертор НЕ ТРОГАТЬ!'!H41="", "", 'Заполняет конвертор НЕ ТРОГАТЬ!'!H41) | B12: =IF('Заполняет конвертор НЕ ТРОГАТЬ!'!I41="", "", 'Заполняет конвертор НЕ ТРОГАТЬ!'!I41) | C12: =IF('Заполняет конвертор НЕ ТРОГАТЬ!'!J41="", "", 'Заполняет конвертор НЕ ТРОГАТЬ!'!J41)
A13: =IF('Заполняет конвертор НЕ ТРОГАТЬ!'!H42="", "", 'Заполняет конвертор НЕ ТРОГАТЬ!'!H42) | B13: =IF('Заполняет конвертор НЕ ТРОГАТЬ!'!I42="", "", 'Заполняет конвертор НЕ ТРОГАТЬ!'!I42) | C13: =IF('Заполняет конвертор НЕ ТРОГАТЬ!'!J42="", "", 'Заполняет конвертор НЕ ТРОГАТЬ!'!J42)
... A100: =IF('Заполняет конвертор НЕ ТРОГАТЬ!'!H129="", "", 'Заполняет конвертор НЕ ТРОГАТЬ!'!H129) -> 1 | B100: =IF('Заполняет конвертор НЕ ТРОГАТЬ!'!I129="", "", 'Заполняет конвертор НЕ ТРОГАТЬ!'!I129) | C100: =IF('Заполняет конвертор НЕ ТРОГАТЬ!'!J129="", "", 'Заполняет конвертор НЕ ТРОГАТЬ!'!J129)

Sheet 2-е ИО
A1: ID | B1: HDAT | C1: DIMSB | D1: Ссылка на отчет в Арке
A2: =IF('Заполняет конвертор НЕ ТРОГАТЬ!'!L31="", "", 'Заполняет конвертор НЕ ТРОГАТЬ!'!L31) -> 1 | B2: =IF('Заполняет конвертор НЕ ТРОГАТЬ!'!M31="", "", 'Заполняет конвертор НЕ ТРОГАТЬ!'!M31) | C2: =IF('Заполняет конвертор НЕ ТРОГАТЬ!'!N31="", "", 'Заполняет конвертор НЕ ТРОГАТЬ!'!N31)
A3: =IF('Заполняет конвертор НЕ ТРОГАТЬ!'!L32="", "", 'Заполняет конвертор НЕ ТРОГАТЬ!'!L32) | B3: =IF('Заполняет конвертор НЕ ТРОГАТЬ!'!M32="", "", 'Заполняет конвертор НЕ ТРОГАТЬ!'!M32) -> 2 | C3: =IF('Заполняет конвертор НЕ ТРОГАТЬ!'!N32="", "", 'Заполняет конвертор НЕ ТРОГАТЬ!'!N32)
A4: =IF('Заполняет конвертор НЕ ТРОГАТЬ!'!L33="", "", 'Заполняет конвертор НЕ ТРОГАТЬ!'!L33) | B4: =IF('Заполняет конвертор НЕ ТРОГАТЬ!'!M33="", "", 'Заполняет конвертор НЕ ТРОГАТЬ!'!M33) | C4: =IF('Заполняет конвертор НЕ ТРОГАТЬ!'!N33="", "", 'Заполняет конвертор НЕ ТРОГАТЬ!'!N33) -> 3
A5: =IF('Заполняет конвертор НЕ ТРОГАТЬ!'!L34="", "", 'Заполняет конвертор НЕ ТРОГАТЬ!'!L34) | B5: =IF('Заполняет конвертор НЕ ТРОГАТЬ!'!M34="", "", 'Заполняет конвертор НЕ ТРОГАТЬ!'!M34) | C5: =IF('Заполняет конвертор НЕ ТРОГАТЬ!'!N34="", "", 'Заполняет конвертор НЕ ТРОГАТЬ!'!N34)
A6: =IF('Заполняет конвертор НЕ ТРОГАТЬ!'!L35="", "", 'Заполняет конвертор НЕ ТРОГАТЬ!'!L35) | B6: =IF('Заполняет конвертор НЕ ТРОГАТЬ!'!M35="", "", 'Заполняет конвертор НЕ ТРОГАТЬ!'!M35) | C6: =IF('Заполняет конвертор НЕ ТРОГАТЬ!'!N35="", "", 'Заполняет конвертор НЕ ТРОГАТЬ!'!N35)
A7: =IF('Заполняет конвертор НЕ ТРОГАТЬ!'!L36="", "", 'Заполняет конвертор НЕ ТРОГАТЬ!'!L36) | B7: =IF('Заполняет конвертор НЕ ТРОГАТЬ!'!M36="", "", 'Заполняет конвертор НЕ ТРОГАТЬ!'!M36) | C7: =IF('Заполняет конвертор НЕ ТРОГАТЬ!'!N36="", "", 'Заполняет конвертор НЕ ТРОГАТЬ!'!N36)
A8: =IF('Заполняет конвертор НЕ ТРОГАТЬ!'!L37="", "", 'Заполняет конвертор НЕ ТРОГАТЬ!'!L37) | B8: =IF('Заполняет конвертор НЕ ТРОГАТЬ!'!M37="", "", 'Заполняет конвертор НЕ ТРОГАТЬ!'!M37) | C8: =IF('Заполняет конвертор НЕ ТРОГАТЬ!'!N37="", "", 'Заполняет конвертор НЕ ТРОГАТЬ!'!N37)
A9: =IF('Заполняет конвертор НЕ ТРОГАТЬ!'!L38="", "", 'Заполняет конвертор НЕ ТРОГАТЬ!'!L38) | B9: =IF('Заполняет конвертор НЕ ТРОГАТЬ!'!M38="", "", 'Заполняет конвертор НЕ ТРОГАТЬ!'!M38) | C9: =IF('Заполняет конвертор НЕ ТРОГАТЬ!'!N38="", "", 'Заполняет конвертор НЕ ТРОГАТЬ!'!N38)
A10: =IF('Заполняет конвертор НЕ ТРОГАТЬ!'!L39="", "", 'Заполняет конвертор НЕ ТРОГАТЬ!'!L39) | B10: =IF('Заполняет конвертор НЕ ТРОГАТЬ!'!M39="", "", 'Заполняет конвертор НЕ ТРОГАТЬ!'!M39) | C10: =IF('Заполняет конвертор НЕ ТРОГАТЬ!'!N39="", "", 'Заполняет конвертор НЕ ТРОГАТЬ!'!N39)
A11: =IF('Заполняет конвертор НЕ ТРОГАТЬ!'!L40="", "", 'Заполняет конвертор НЕ ТРОГАТЬ!'!L40) | B11: =IF('Заполняет конвертор НЕ ТРОГАТЬ!'!M40="", "", 'Заполняет конвертор НЕ ТРОГАТЬ!'!M40) | C11: =IF('Заполняет конвертор НЕ ТРОГАТЬ!'!N40="", "", 'Заполняет конвертор НЕ ТРОГАТЬ!'!N40)
A12: =IF('Заполняет конвертор НЕ ТРОГАТЬ!'!L41="", "", 'Заполняет конвертор НЕ ТРОГАТЬ!'!L41) | B12: =IF('Заполняет конвертор НЕ ТРОГАТЬ!'!M41="", "", 'Заполняет конвертор НЕ ТРОГАТЬ!'!M41) | C12: =IF('Заполняет конвертор НЕ ТРОГАТЬ!'!N41="", "", 'Заполняет конвертор НЕ ТРОГАТЬ!'!N41)
A13: =IF('Заполняет конвертор НЕ ТРОГАТЬ!'!L42="", "", 'Заполняет конвертор НЕ ТРОГАТЬ!'!L42) | B13: =IF('Заполняет конвертор НЕ ТРОГАТЬ!'!M42="", "", 'Заполняет конвертор НЕ ТРОГАТЬ!'!M42) | C13: =IF('Заполняет конвертор НЕ ТРОГАТЬ!'!N42="", "", 'Заполняет конвертор НЕ ТРОГАТЬ!'!N42)
... A99: =IF('Заполняет конвертор НЕ ТРОГАТЬ!'!L128="", "", 'Заполняет конвертор НЕ ТРОГАТЬ!'!L128) -> 2 | B99: =IF('Заполняет конвертор НЕ ТРОГАТЬ!'!M128="", "", 'Заполняет конвертор НЕ ТРОГАТЬ!'!M128) | C99: =IF('Заполняет конвертор НЕ ТРОГАТЬ!'!N128="", "", 'Заполняет конвертор НЕ ТРОГАТЬ!'!N128)

Sheet Результат отёла
A1: Дата отёла | B1: Прц | C1: Кол-в | D1: Телка | E1: Бычок | M1: Скопируй таблицу и вставь сюда
A2: =M5 -> 46243 | B2: 0 | C2: 0 | D2: =O5 -> 12 | E2: =P5 -> 5
A3: =M6 -> 46244 | D3: =O6 -> 9 | E3: =P6 -> 5
A4: =M7 -> 46245 | D4: =O7 -> 11 | E4: =P7 -> 4 | M4: День | N4: Число отёлов | O4: Родилось тёлок | P4: Родилось быков
A5: =M8 -> 46246 | D5: =O8 -> 5 | E5: =P8 -> 3 | M5: =IF('Заполняет конвертор НЕ ТРОГАТЬ!'!A79="", "", 'Заполняет конвертор НЕ ТРОГАТЬ!'!A79) -> 46243 | N5: =IF('Заполняет конвертор НЕ ТРОГАТЬ!'!B79="", "", 'Заполняет конвертор НЕ ТРОГАТЬ!'!B79) -> 17 | O5: =IF('Заполняет конвертор НЕ ТРОГАТЬ!'!C79="", "", 'Заполняет конвертор НЕ ТРОГАТЬ!'!C79) -> 12 | P5: =IF('Заполняет конвертор НЕ ТРОГАТЬ!'!D79="", "", 'Заполняет конвертор НЕ ТРОГАТЬ!'!D79) -> 5
A6: =M9 -> 46247 | D6: =O9 -> 11 | E6: =P9 -> 2 | M6: =IF('Заполняет конвертор НЕ ТРОГАТЬ!'!A80="", "", 'Заполняет конвертор НЕ ТРОГАТЬ!'!A80) -> 46244 | N6: =IF('Заполняет конвертор НЕ ТРОГАТЬ!'!B80="", "", 'Заполняет конвертор НЕ ТРОГАТЬ!'!B80) -> 14 | O6: =IF('Заполняет конвертор НЕ ТРОГАТЬ!'!C80="", "", 'Заполняет конвертор НЕ ТРОГАТЬ!'!C80) -> 9 | P6: =IF('Заполняет конвертор НЕ ТРОГАТЬ!'!D80="", "", 'Заполняет конвертор НЕ ТРОГАТЬ!'!D80) -> 5
A7: =M10 -> 46248 | D7: =O10 -> 12 | E7: =P10 -> 4 | M7: =IF('Заполняет конвертор НЕ ТРОГАТЬ!'!A81="", "", 'Заполняет конвертор НЕ ТРОГАТЬ!'!A81) -> 46245 | N7: =IF('Заполняет конвертор НЕ ТРОГАТЬ!'!B81="", "", 'Заполняет конвертор НЕ ТРОГАТЬ!'!B81) -> 15 | O7: =IF('Заполняет конвертор НЕ ТРОГАТЬ!'!C81="", "", 'Заполняет конвертор НЕ ТРОГАТЬ!'!C81) -> 11 | P7: =IF('Заполняет конвертор НЕ ТРОГАТЬ!'!D81="", "", 'Заполняет конвертор НЕ ТРОГАТЬ!'!D81) -> 4
A8: =M11 -> 46249 | D8: =O11 -> 3 | E8: =P11 -> 0 | M8: =IF('Заполняет конвертор НЕ ТРОГАТЬ!'!A82="", "", 'Заполняет конвертор НЕ ТРОГАТЬ!'!A82) -> 46246 | N8: =IF('Заполняет конвертор НЕ ТРОГАТЬ!'!B82="", "", 'Заполняет конвертор НЕ ТРОГАТЬ!'!B82) -> 8 | O8: =IF('Заполняет конвертор НЕ ТРОГАТЬ!'!C82="", "", 'Заполняет конвертор НЕ ТРОГАТЬ!'!C82) -> 5 | P8: =IF('Заполняет конвертор НЕ ТРОГАТЬ!'!D82="", "", 'Заполняет конвертор НЕ ТРОГАТЬ!'!D82) -> 3
D9: =O12 -> 0 | E9: =P12 -> 0 | M9: =IF('Заполняет конвертор НЕ ТРОГАТЬ!'!A83="", "", 'Заполняет конвертор НЕ ТРОГАТЬ!'!A83) -> 46247 | N9: =IF('Заполняет конвертор НЕ ТРОГАТЬ!'!B83="", "", 'Заполняет конвертор НЕ ТРОГАТЬ!'!B83) -> 13 | O9: =IF('Заполняет конвертор НЕ ТРОГАТЬ!'!C83="", "", 'Заполняет конвертор НЕ ТРОГАТЬ!'!C83) -> 11 | P9: =IF('Заполняет конвертор НЕ ТРОГАТЬ!'!D83="", "", 'Заполняет конвертор НЕ ТРОГАТЬ!'!D83) -> 2
M10: =IF('Заполняет конвертор НЕ ТРОГАТЬ!'!A84="", "", 'Заполняет конвертор НЕ ТРОГАТЬ!'!A84) -> 46248 | N10: =IF('Заполняет конвертор НЕ ТРОГАТЬ!'!B84="", "", 'Заполняет конвертор НЕ ТРОГАТЬ!'!B84) -> 16 | O10: =IF('Заполняет конвертор НЕ ТРОГАТЬ!'!C84="", "", 'Заполняет конвертор НЕ ТРОГАТЬ!'!C84) -> 12 | P10: =IF('Заполняет конвертор НЕ ТРОГАТЬ!'!D84="", "", 'Заполняет конвертор НЕ ТРОГАТЬ!'!D84) -> 4
M11: =IF('Заполняет конвертор НЕ ТРОГАТЬ!'!A85="", "", 'Заполняет конвертор НЕ ТРОГАТЬ!'!A85) -> 46249 | N11: =IF('Заполняет конвертор НЕ ТРОГАТЬ!'!B85="", "", 'Заполняет конвертор НЕ ТРОГАТЬ!'!B85) -> 3 | O11: =IF('Заполняет конвертор НЕ ТРОГАТЬ!'!C85="", "", 'Заполняет конвертор НЕ ТРОГАТЬ!'!C85) -> 3 | P11: =IF('Заполняет конвертор НЕ ТРОГАТЬ!'!D85="", "", 'Заполняет конвертор НЕ ТРОГАТЬ!'!D85) -> 0
A13: Ссылка на отчет в Арке

Sheet Проверка УЗИ
A1: 0 | B1: Процент | C1: Событие | D1: Всего
A2: Стельные | B2: =IFERROR(D2/D4,0) -> 0.5 | C2: СТЕЛ | D2: =SUM('Стельность сухостой'!C4:C33) -> 1
A3: Холостые | B3: =IFERROR(D3/D4,0) -> 0.5 | C3: ЯЛОВ | D3: =SUM('Стельность сухостой'!B4:B33) -> 1
A4: ИТОГО | C4: ИТОГО | D4: =SUM(D2:D3) -> 2
A7: Дата | B7: 46243

Sheet Выбытие телят до 6 месяцев
A1: Ссылка на отчет в Арке | L1: Дата выбытия | M1: Продажа | N1: Падёж | P1: Сумма
A2: Дата выбытия | B2: Прц | C2: Кол-в | L2: =IF('Заполняет конвертор НЕ ТРОГАТЬ!'!A90="", "", 'Заполняет конвертор НЕ ТРОГАТЬ!'!A90) -> 46237 | M2: =IF('Заполняет конвертор НЕ ТРОГАТЬ!'!B90="", "", 'Заполняет конвертор НЕ ТРОГАТЬ!'!B90) -> 0 | N2: =IF('Заполняет конвертор НЕ ТРОГАТЬ!'!C90="", "", 'Заполняет конвертор НЕ ТРОГАТЬ!'!C90) -> 1 | P2: =M2+N2 -> 1
A3: =A4-1 -> 46218 | B3: 0 | C3: =IFERROR(_xlfn.XLOOKUP(A3,$L$2:$L$21,$P$2:$P$21),0) -> 0 | L3: =IF('Заполняет конвертор НЕ ТРОГАТЬ!'!A91="", "", 'Заполняет конвертор НЕ ТРОГАТЬ!'!A91) | M3: =IF('Заполняет конвертор НЕ ТРОГАТЬ!'!B91="", "", 'Заполняет конвертор НЕ ТРОГАТЬ!'!B91) | N3: =IF('Заполняет конвертор НЕ ТРОГАТЬ!'!C91="", "", 'Заполняет конвертор НЕ ТРОГАТЬ!'!C91) | P3: =M3+N3 -> #VALUE!
A4: =A5-1 -> 46219 | B4: 0 | C4: =IFERROR(_xlfn.XLOOKUP(A4,$L$2:$L$21,$P$2:$P$21),0) -> 0 | L4: =IF('Заполняет конвертор НЕ ТРОГАТЬ!'!A92="", "", 'Заполняет конвертор НЕ ТРОГАТЬ!'!A92) | M4: =IF('Заполняет конвертор НЕ ТРОГАТЬ!'!B92="", "", 'Заполняет конвертор НЕ ТРОГАТЬ!'!B92) | N4: =IF('Заполняет конвертор НЕ ТРОГАТЬ!'!C92="", "", 'Заполняет конвертор НЕ ТРОГАТЬ!'!C92) | P4: =M4+N4 -> #VALUE!
A5: =A6-1 -> 46220 | B5: 0 | C5: =IFERROR(_xlfn.XLOOKUP(A5,$L$2:$L$21,$P$2:$P$21),0) -> 0 | L5: =IF('Заполняет конвертор НЕ ТРОГАТЬ!'!A93="", "", 'Заполняет конвертор НЕ ТРОГАТЬ!'!A93) | M5: =IF('Заполняет конвертор НЕ ТРОГАТЬ!'!B93="", "", 'Заполняет конвертор НЕ ТРОГАТЬ!'!B93) | N5: =IF('Заполняет конвертор НЕ ТРОГАТЬ!'!C93="", "", 'Заполняет конвертор НЕ ТРОГАТЬ!'!C93) | P5: =M5+N5 -> #VALUE!
A6: =A7-1 -> 46221 | B6: 0 | C6: =IFERROR(_xlfn.XLOOKUP(A6,$L$2:$L$21,$P$2:$P$21),0) -> 0 | L6: =IF('Заполняет конвертор НЕ ТРОГАТЬ!'!A94="", "", 'Заполняет конвертор НЕ ТРОГАТЬ!'!A94) | M6: =IF('Заполняет конвертор НЕ ТРОГАТЬ!'!B94="", "", 'Заполняет конвертор НЕ ТРОГАТЬ!'!B94) | N6: =IF('Заполняет конвертор НЕ ТРОГАТЬ!'!C94="", "", 'Заполняет конвертор НЕ ТРОГАТЬ!'!C94) | P6: =M6+N6 -> #VALUE!
A7: =A8-1 -> 46222 | B7: 0 | C7: =IFERROR(_xlfn.XLOOKUP(A7,$L$2:$L$21,$P$2:$P$21),0) -> 0 | L7: =IF('Заполняет конвертор НЕ ТРОГАТЬ!'!A95="", "", 'Заполняет конвертор НЕ ТРОГАТЬ!'!A95) | M7: =IF('Заполняет конвертор НЕ ТРОГАТЬ!'!B95="", "", 'Заполняет конвертор НЕ ТРОГАТЬ!'!B95) | N7: =IF('Заполняет конвертор НЕ ТРОГАТЬ!'!C95="", "", 'Заполняет конвертор НЕ ТРОГАТЬ!'!C95) | P7: =M7+N7 -> #VALUE!
A8: =A9-1 -> 46223 | B8: 0 | C8: =IFERROR(_xlfn.XLOOKUP(A8,$L$2:$L$21,$P$2:$P$21),0) -> 0 | L8: =IF('Заполняет конвертор НЕ ТРОГАТЬ!'!A96="", "", 'Заполняет конвертор НЕ ТРОГАТЬ!'!A96) | M8: =IF('Заполняет конвертор НЕ ТРОГАТЬ!'!B96="", "", 'Заполняет конвертор НЕ ТРОГАТЬ!'!B96) | N8: =IF('Заполняет конвертор НЕ ТРОГАТЬ!'!C96="", "", 'Заполняет конвертор НЕ ТРОГАТЬ!'!C96) | P8: =M8+N8 -> #VALUE!
A9: =A10-1 -> 46224 | B9: 0 | C9: =IFERROR(_xlfn.XLOOKUP(A9,$L$2:$L$21,$P$2:$P$21),0) -> 0 | L9: =IF('Заполняет конвертор НЕ ТРОГАТЬ!'!A97="", "", 'Заполняет конвертор НЕ ТРОГАТЬ!'!A97) | M9: =IF('Заполняет конвертор НЕ ТРОГАТЬ!'!B97="", "", 'Заполняет конвертор НЕ ТРОГАТЬ!'!B97) | N9: =IF('Заполняет конвертор НЕ ТРОГАТЬ!'!C97="", "", 'Заполняет конвертор НЕ ТРОГАТЬ!'!C97) | P9: =M9+N9 -> #VALUE!
A10: =A11-1 -> 46225 | B10: 0 | C10: =IFERROR(_xlfn.XLOOKUP(A10,$L$2:$L$21,$P$2:$P$21),0) -> 0 | L10: =IF('Заполняет конвертор НЕ ТРОГАТЬ!'!A98="", "", 'Заполняет конвертор НЕ ТРОГАТЬ!'!A98) | M10: =IF('Заполняет конвертор НЕ ТРОГАТЬ!'!B98="", "", 'Заполняет конвертор НЕ ТРОГАТЬ!'!B98) | N10: =IF('Заполняет конвертор НЕ ТРОГАТЬ!'!C98="", "", 'Заполняет конвертор НЕ ТРОГАТЬ!'!C98) | P10: =M10+N10 -> #VALUE!
A11: =A12-1 -> 46226 | B11: 0 | C11: =IFERROR(_xlfn.XLOOKUP(A11,$L$2:$L$21,$P$2:$P$21),0) -> 0 | L11: =IF('Заполняет конвертор НЕ ТРОГАТЬ!'!A99="", "", 'Заполняет конвертор НЕ ТРОГАТЬ!'!A99) | M11: =IF('Заполняет конвертор НЕ ТРОГАТЬ!'!B99="", "", 'Заполняет конвертор НЕ ТРОГАТЬ!'!B99) | N11: =IF('Заполняет конвертор НЕ ТРОГАТЬ!'!C99="", "", 'Заполняет конвертор НЕ ТРОГАТЬ!'!C99) | P11: =M11+N11 -> #VALUE!
A12: =A13-1 -> 46227 | B12: 0 | C12: =IFERROR(_xlfn.XLOOKUP(A12,$L$2:$L$21,$P$2:$P$21),0) -> 0 | L12: =IF('Заполняет конвертор НЕ ТРОГАТЬ!'!A100="", "", 'Заполняет конвертор НЕ ТРОГАТЬ!'!A100) | M12: =IF('Заполняет конвертор НЕ ТРОГАТЬ!'!B100="", "", 'Заполняет конвертор НЕ ТРОГАТЬ!'!B100) | N12: =IF('Заполняет конвертор НЕ ТРОГАТЬ!'!C100="", "", 'Заполняет конвертор НЕ ТРОГАТЬ!'!C100) | P12: =M12+N12 -> #VALUE!
A13: =A14-1 -> 46228 | B13: 0 | C13: =IFERROR(_xlfn.XLOOKUP(A13,$L$2:$L$21,$P$2:$P$21),0) -> 0 | L13: =IF('Заполняет конвертор НЕ ТРОГАТЬ!'!A101="", "", 'Заполняет конвертор НЕ ТРОГАТЬ!'!A101) | M13: =IF('Заполняет конвертор НЕ ТРОГАТЬ!'!B101="", "", 'Заполняет конвертор НЕ ТРОГАТЬ!'!B101) | N13: =IF('Заполняет конвертор НЕ ТРОГАТЬ!'!C101="", "", 'Заполняет конвертор НЕ ТРОГАТЬ!'!C101) | P13: =M13+N13 -> #VALUE!
A14: =A15-1 -> 46229 | B14: 0 | C14: =IFERROR(_xlfn.XLOOKUP(A14,$L$2:$L$21,$P$2:$P$21),0) -> 0 | L14: =IF('Заполняет конвертор НЕ ТРОГАТЬ!'!A102="", "", 'Заполняет конвертор НЕ ТРОГАТЬ!'!A102) | M14: =IF('Заполняет конвертор НЕ ТРОГАТЬ!'!B102="", "", 'Заполняет конвертор НЕ ТРОГАТЬ!'!B102) | N14: =IF('Заполняет конвертор НЕ ТРОГАТЬ!'!C102="", "", 'Заполняет конвертор НЕ ТРОГАТЬ!'!C102) | P14: =M14+N14 -> #VALUE!
... A19: =A20-1 -> 46234 | B19: 0 | C19: =IFERROR(_xlfn.XLOOKUP(A19,$L$2:$L$21,$P$2:$P$21),0) -> 0 | L19: =IF('Заполняет конвертор НЕ ТРОГАТЬ!'!A107="", "", 'Заполняет конвертор НЕ ТРОГАТЬ!'!A107) | M19: =IF('Заполняет конвертор НЕ ТРОГАТЬ!'!B107="", "", 'Заполняет конвертор НЕ ТРОГАТЬ!'!B107) | N19: =IF('Заполняет конвертор НЕ ТРОГАТЬ!'!C107="", "", 'Заполняет конвертор НЕ ТРОГАТЬ!'!C107) | P19: =M19+N19 -> #VALUE!
A20: =A21-1 -> 46235 | B20: 0 | C20: =IFERROR(_xlfn.XLOOKUP(A20,$L$2:$L$34,$P$2:$P$34),0) -> 3 | L20: =IF('Заполняет конвертор НЕ ТРОГАТЬ!'!A108="", "", 'Заполняет конвертор НЕ ТРОГАТЬ!'!A108) | M20: =IF('Заполняет конвертор НЕ ТРОГАТЬ!'!B108="", "", 'Заполняет конвертор НЕ ТРОГАТЬ!'!B108) | N20: =IF('Заполняет конвертор НЕ ТРОГАТЬ!'!C108="", "", 'Заполняет конвертор НЕ ТРОГАТЬ!'!C108) | P20: =M20+N20 -> #VALUE!
A21: =A22-1 -> 46236 | B21: 0 | C21: =IFERROR(_xlfn.XLOOKUP(A21,$L$2:$L$21,$P$2:$P$21),0) -> 0 | L21: =IF('Заполняет конвертор НЕ ТРОГАТЬ!'!A109="", "", 'Заполняет конвертор НЕ ТРОГАТЬ!'!A109) | M21: =IF('Заполняет конвертор НЕ ТРОГАТЬ!'!B109="", "", 'Заполняет конвертор НЕ ТРОГАТЬ!'!B109) | N21: =IF('Заполняет конвертор НЕ ТРОГАТЬ!'!C109="", "", 'Заполняет конвертор НЕ ТРОГАТЬ!'!C109) | P21: =M21+N21 -> #VALUE!
A22: =A23-1 -> 46237 | B22: 0 | C22: =IFERROR(_xlfn.XLOOKUP(A22,$L$2:$L$21,$P$2:$P$21),0) -> 1 | L22: =IF('Заполняет конвертор НЕ ТРОГАТЬ!'!A110="", "", 'Заполняет конвертор НЕ ТРОГАТЬ!'!A110) | M22: =IF('Заполняет конвертор НЕ ТРОГАТЬ!'!B110="", "", 'Заполняет конвертор НЕ ТРОГАТЬ!'!B110) | N22: =IF('Заполняет конвертор НЕ ТРОГАТЬ!'!C110="", "", 'Заполняет конвертор НЕ ТРОГАТЬ!'!C110) | P22: =M22+N22 -> #VALUE!
A23: =A24-1 -> 46238 | B23: 0 | C23: =IFERROR(_xlfn.XLOOKUP(A23,$L$2:$L$21,$P$2:$P$21),0) -> 0 | L23: =IF('Заполняет конвертор НЕ ТРОГАТЬ!'!A111="", "", 'Заполняет конвертор НЕ ТРОГАТЬ!'!A111) | M23: =IF('Заполняет конвертор НЕ ТРОГАТЬ!'!B111="", "", 'Заполняет конвертор НЕ ТРОГАТЬ!'!B111) | N23: =IF('Заполняет конвертор НЕ ТРОГАТЬ!'!C111="", "", 'Заполняет конвертор НЕ ТРОГАТЬ!'!C111) | P23: =M23+N23 -> #VALUE!
A24: =A25-1 -> 46239 | B24: 0 | C24: =IFERROR(_xlfn.XLOOKUP(A24,$L$2:$L$21,$P$2:$P$21),0) -> 0 | L24: =IF('Заполняет конвертор НЕ ТРОГАТЬ!'!A112="", "", 'Заполняет конвертор НЕ ТРОГАТЬ!'!A112) | M24: =IF('Заполняет конвертор НЕ ТРОГАТЬ!'!B112="", "", 'Заполняет конвертор НЕ ТРОГАТЬ!'!B112) | N24: =IF('Заполняет конвертор НЕ ТРОГАТЬ!'!C112="", "", 'Заполняет конвертор НЕ ТРОГАТЬ!'!C112) | P24: =M24+N24 -> #VALUE!
A25: =A26-1 -> 46240 | B25: 0 | C25: =IFERROR(_xlfn.XLOOKUP(A25,$L$2:$L$21,$P$2:$P$21),0) -> 0 | L25: =IF('Заполняет конвертор НЕ ТРОГАТЬ!'!A113="", "", 'Заполняет конвертор НЕ ТРОГАТЬ!'!A113) | M25: =IF('Заполняет конвертор НЕ ТРОГАТЬ!'!B113="", "", 'Заполняет конвертор НЕ ТРОГАТЬ!'!B113) | N25: =IF('Заполняет конвертор НЕ ТРОГАТЬ!'!C113="", "", 'Заполняет конвертор НЕ ТРОГАТЬ!'!C113) | P25: =M25+N25 -> #VALUE!
A26: =A27-1 -> 46241 | B26: 0 | C26: =IFERROR(_xlfn.XLOOKUP(A26,$L$2:$L$21,$P$2:$P$21),0) -> 0 | L26: =IF('Заполняет конвертор НЕ ТРОГАТЬ!'!A114="", "", 'Заполняет конвертор НЕ ТРОГАТЬ!'!A114) | M26: =IF('Заполняет конвертор НЕ ТРОГАТЬ!'!B114="", "", 'Заполняет конвертор НЕ ТРОГАТЬ!'!B114) | N26: =IF('Заполняет конвертор НЕ ТРОГАТЬ!'!C114="", "", 'Заполняет конвертор НЕ ТРОГАТЬ!'!C114) | P26: =M26+N26 -> #VALUE!
A27: =A28-1 -> 46242 | B27: 0 | C27: =IFERROR(_xlfn.XLOOKUP(A27,$L$2:$L$21,$P$2:$P$21),0) -> 0 | L27: =IF('Заполняет конвертор НЕ ТРОГАТЬ!'!A115="", "", 'Заполняет конвертор НЕ ТРОГАТЬ!'!A115) | M27: =IF('Заполняет конвертор НЕ ТРОГАТЬ!'!B115="", "", 'Заполняет конвертор НЕ ТРОГАТЬ!'!B115) | N27: =IF('Заполняет конвертор НЕ ТРОГАТЬ!'!C115="", "", 'Заполняет конвертор НЕ ТРОГАТЬ!'!C115) | P27: =M27+N27 -> #VALUE!
A28: =A29-1 -> 46243 | B28: 0 | C28: =IFERROR(_xlfn.XLOOKUP(A28,$L$2:$L$21,$P$2:$P$21),0) -> 0 | L28: =IF('Заполняет конвертор НЕ ТРОГАТЬ!'!A116="", "", 'Заполняет конвертор НЕ ТРОГАТЬ!'!A116) | M28: =IF('Заполняет конвертор НЕ ТРОГАТЬ!'!B116="", "", 'Заполняет конвертор НЕ ТРОГАТЬ!'!B116) | N28: =IF('Заполняет конвертор НЕ ТРОГАТЬ!'!C116="", "", 'Заполняет конвертор НЕ ТРОГАТЬ!'!C116) | P28: =M28+N28 -> #VALUE!
A29: =A30-1 -> 46244 | B29: 0 | C29: =IFERROR(_xlfn.XLOOKUP(A29,$L$2:$L$21,$P$2:$P$21),0) -> 0 | L29: =IF('Заполняет конвертор НЕ ТРОГАТЬ!'!A117="", "", 'Заполняет конвертор НЕ ТРОГАТЬ!'!A117) | M29: =IF('Заполняет конвертор НЕ ТРОГАТЬ!'!B117="", "", 'Заполняет конвертор НЕ ТРОГАТЬ!'!B117) | N29: =IF('Заполняет конвертор НЕ ТРОГАТЬ!'!C117="", "", 'Заполняет конвертор НЕ ТРОГАТЬ!'!C117) | P29: =M29+N29 -> #VALUE!
A30: =A31-1 -> 46245 | B30: 0 | C30: =IFERROR(_xlfn.XLOOKUP(A30,$L$2:$L$21,$P$2:$P$21),0) -> 0 | L30: =IF('Заполняет конвертор НЕ ТРОГАТЬ!'!A118="", "", 'Заполняет конвертор НЕ ТРОГАТЬ!'!A118) | M30: =IF('Заполняет конвертор НЕ ТРОГАТЬ!'!B118="", "", 'Заполняет конвертор НЕ ТРОГАТЬ!'!B118) | N30: =IF('Заполняет конвертор НЕ ТРОГАТЬ!'!C118="", "", 'Заполняет конвертор НЕ ТРОГАТЬ!'!C118) | P30: =M30+N30 -> #VALUE!
A31: =A32-1 -> 46246 | B31: 0 | C31: =IFERROR(_xlfn.XLOOKUP(A31,$L$2:$L$21,$P$2:$P$21),0) -> 0 | L31: =IF('Заполняет конвертор НЕ ТРОГАТЬ!'!A119="", "", 'Заполняет конвертор НЕ ТРОГАТЬ!'!A119) | M31: =IF('Заполняет конвертор НЕ ТРОГАТЬ!'!B119="", "", 'Заполняет конвертор НЕ ТРОГАТЬ!'!B119) | N31: =IF('Заполняет конвертор НЕ ТРОГАТЬ!'!C119="", "", 'Заполняет конвертор НЕ ТРОГАТЬ!'!C119) | P31: =M31+N31 -> #VALUE!
A32: =A33-1 -> 46247 | B32: 0 | C32: =IFERROR(_xlfn.XLOOKUP(A32,$L$2:$L$21,$P$2:$P$21),0) -> 0 | L32: =IF('Заполняет конвертор НЕ ТРОГАТЬ!'!A120="", "", 'Заполняет конвертор НЕ ТРОГАТЬ!'!A120) | M32: =IF('Заполняет конвертор НЕ ТРОГАТЬ!'!B120="", "", 'Заполняет конвертор НЕ ТРОГАТЬ!'!B120) | N32: =IF('Заполняет конвертор НЕ ТРОГАТЬ!'!C120="", "", 'Заполняет конвертор НЕ ТРОГАТЬ!'!C120) | P32: =M32+N32 -> #VALUE!
A33: =A34-1 -> 46248 | B33: 0 | C33: =IFERROR(_xlfn.XLOOKUP(A33,$L$2:$L$21,$P$2:$P$21),0) -> 0 | L33: =IF('Заполняет конвертор НЕ ТРОГАТЬ!'!A121="", "", 'Заполняет конвертор НЕ ТРОГАТЬ!'!A121) | M33: =IF('Заполняет конвертор НЕ ТРОГАТЬ!'!B121="", "", 'Заполняет конвертор НЕ ТРОГАТЬ!'!B121) | N33: =IF('Заполняет конвертор НЕ ТРОГАТЬ!'!C121="", "", 'Заполняет конвертор НЕ ТРОГАТЬ!'!C121) | P33: =M33+N33 -> #VALUE!
A34: 46249 | B34: 0 | C34: =IFERROR(_xlfn.XLOOKUP(A34,$L$2:$L$21,$P$2:$P$21),0) -> 0 | L34: =IF('Заполняет конвертор НЕ ТРОГАТЬ!'!A122="", "", 'Заполняет конвертор НЕ ТРОГАТЬ!'!A122) -> 46235 | M34: =IF('Заполняет конвертор НЕ ТРОГАТЬ!'!B122="", "", 'Заполняет конвертор НЕ ТРОГАТЬ!'!B122) -> 1 | N34: =IF('Заполняет конвертор НЕ ТРОГАТЬ!'!C122="", "", 'Заполняет конвертор НЕ ТРОГАТЬ!'!C122) -> 2 | P34: =M34+N34 -> 3

Sheet Выбытие до 60 дней  за год
A1: МЕСЯЦ | B1: ОТЕЛ | C1: ВЫБЫТИЕ | D1: СОХРАННОСТЬ | E1: ВЫБЫТИЕ %
A2: =M3 -> сен 2025 | B2: =N3+P3 -> 462 | C2: =O3+Q3 -> 70 | D2: =IFERROR((B2-C2)/B2,0) -> 0.84848485 | E2: =IFERROR(C2/B2,0) -> 0.15151515 | M2: Месяц и год отёла | N2: Отел | O2: Падёж | P2: Аборт | Q2: Продажа
A3: =M4 -> 45931 | B3: =N4+P4 -> 460 | C3: =O4+Q4 -> 46 | D3: =IFERROR((B3-C3)/B3,0) -> 0.9 | E3: =IFERROR(C3/B3,0) -> 0.1 | M3: =IF('Заполняет конвертор НЕ ТРОГАТЬ!'!A126="", "", 'Заполняет конвертор НЕ ТРОГАТЬ!'!A126) -> сен 2025 | N3: =IF('Заполняет конвертор НЕ ТРОГАТЬ!'!B126="", "", 'Заполняет конвертор НЕ ТРОГАТЬ!'!B126) -> 455 | O3: =IF('Заполняет конвертор НЕ ТРОГАТЬ!'!C126="", "", 'Заполняет конвертор НЕ ТРОГАТЬ!'!C126) -> 14 | P3: =IF('Заполняет конвертор НЕ ТРОГАТЬ!'!D126="", "", 'Заполняет конвертор НЕ ТРОГАТЬ!'!D126) -> 7 | Q3: =IF('Заполняет конвертор НЕ ТРОГАТЬ!'!E126="", "", 'Заполняет конвертор НЕ ТРОГАТЬ!'!E126) -> 56
A4: =M5 -> ноя 2025 | B4: =N5+P5 -> 314 | C4: =O5+Q5 -> 37 | D4: =IFERROR((B4-C4)/B4,0) -> 0.88216561 | E4: =IFERROR(C4/B4,0) -> 0.11783439 | M4: =IF('Заполняет конвертор НЕ ТРОГАТЬ!'!A127="", "", 'Заполняет конвертор НЕ ТРОГАТЬ!'!A127) -> 45931 | N4: =IF('Заполняет конвертор НЕ ТРОГАТЬ!'!B127="", "", 'Заполняет конвертор НЕ ТРОГАТЬ!'!B127) -> 454 | O4: =IF('Заполняет конвертор НЕ ТРОГАТЬ!'!C127="", "", 'Заполняет конвертор НЕ ТРОГАТЬ!'!C127) -> 9 | P4: =IF('Заполняет конвертор НЕ ТРОГАТЬ!'!D127="", "", 'Заполняет конвертор НЕ ТРОГАТЬ!'!D127) -> 6 | Q4: =IF('Заполняет конвертор НЕ ТРОГАТЬ!'!E127="", "", 'Заполняет конвертор НЕ ТРОГАТЬ!'!E127) -> 37
A5: =M6 -> 45992 | B5: =N6+P6 -> 477 | C5: =O6+Q6 -> 78 | D5: =IFERROR((B5-C5)/B5,0) -> 0.83647799 | E5: =IFERROR(C5/B5,0) -> 0.16352201 | M5: =IF('Заполняет конвертор НЕ ТРОГАТЬ!'!A128="", "", 'Заполняет конвертор НЕ ТРОГАТЬ!'!A128) -> ноя 2025 | N5: =IF('Заполняет конвертор НЕ ТРОГАТЬ!'!B128="", "", 'Заполняет конвертор НЕ ТРОГАТЬ!'!B128) -> 310 | O5: =IF('Заполняет конвертор НЕ ТРОГАТЬ!'!C128="", "", 'Заполняет конвертор НЕ ТРОГАТЬ!'!C128) -> 8 | P5: =IF('Заполняет конвертор НЕ ТРОГАТЬ!'!D128="", "", 'Заполняет конвертор НЕ ТРОГАТЬ!'!D128) -> 4 | Q5: =IF('Заполняет конвертор НЕ ТРОГАТЬ!'!E128="", "", 'Заполняет конвертор НЕ ТРОГАТЬ!'!E128) -> 29
A6: =M7 -> 46023 | B6: =N7+P7 -> 467 | C6: =O7+Q7 -> 75 | D6: =IFERROR((B6-C6)/B6,0) -> 0.83940043 | E6: =IFERROR(C6/B6,0) -> 0.16059957 | M6: =IF('Заполняет конвертор НЕ ТРОГАТЬ!'!A129="", "", 'Заполняет конвертор НЕ ТРОГАТЬ!'!A129) -> 45992 | N6: =IF('Заполняет конвертор НЕ ТРОГАТЬ!'!B129="", "", 'Заполняет конвертор НЕ ТРОГАТЬ!'!B129) -> 470 | O6: =IF('Заполняет конвертор НЕ ТРОГАТЬ!'!C129="", "", 'Заполняет конвертор НЕ ТРОГАТЬ!'!C129) -> 14 | P6: =IF('Заполняет конвертор НЕ ТРОГАТЬ!'!D129="", "", 'Заполняет конвертор НЕ ТРОГАТЬ!'!D129) -> 7 | Q6: =IF('Заполняет конвертор НЕ ТРОГАТЬ!'!E129="", "", 'Заполняет конвертор НЕ ТРОГАТЬ!'!E129) -> 64
A7: =M8 -> фев 2026 | B7: =N8+P8 -> 446 | C7: =O8+Q8 -> 61 | D7: =IFERROR((B7-C7)/B7,0) -> 0.8632287 | E7: =IFERROR(C7/B7,0) -> 0.1367713 | M7: =IF('Заполняет конвертор НЕ ТРОГАТЬ!'!A130="", "", 'Заполняет конвертор НЕ ТРОГАТЬ!'!A130) -> 46023 | N7: =IF('Заполняет конвертор НЕ ТРОГАТЬ!'!B130="", "", 'Заполняет конвертор НЕ ТРОГАТЬ!'!B130) -> 463 | O7: =IF('Заполняет конвертор НЕ ТРОГАТЬ!'!C130="", "", 'Заполняет конвертор НЕ ТРОГАТЬ!'!C130) -> 10 | P7: =IF('Заполняет конвертор НЕ ТРОГАТЬ!'!D130="", "", 'Заполняет конвертор НЕ ТРОГАТЬ!'!D130) -> 4 | Q7: =IF('Заполняет конвертор НЕ ТРОГАТЬ!'!E130="", "", 'Заполняет конвертор НЕ ТРОГАТЬ!'!E130) -> 65
A8: =M9 -> 46082 | B8: =N9+P9 -> 461 | C8: =O9+Q9 -> 64 | D8: =IFERROR((B8-C8)/B8,0) -> 0.86117137 | E8: =IFERROR(C8/B8,0) -> 0.13882863 | M8: =IF('Заполняет конвертор НЕ ТРОГАТЬ!'!A131="", "", 'Заполняет конвертор НЕ ТРОГАТЬ!'!A131) -> фев 2026 | N8: =IF('Заполняет конвертор НЕ ТРОГАТЬ!'!B131="", "", 'Заполняет конвертор НЕ ТРОГАТЬ!'!B131) -> 444 | O8: =IF('Заполняет конвертор НЕ ТРОГАТЬ!'!C131="", "", 'Заполняет конвертор НЕ ТРОГАТЬ!'!C131) -> 6 | P8: =IF('Заполняет конвертор НЕ ТРОГАТЬ!'!D131="", "", 'Заполняет конвертор НЕ ТРОГАТЬ!'!D131) -> 2 | Q8: =IF('Заполняет конвертор НЕ ТРОГАТЬ!'!E131="", "", 'Заполняет конвертор НЕ ТРОГАТЬ!'!E131) -> 55
A9: =M10 -> 46113 | B9: =N10+P10 -> 317 | C9: =O10+Q10 -> 50 | D9: =IFERROR((B9-C9)/B9,0) -> 0.84227129 | E9: =IFERROR(C9/B9,0) -> 0.15772871 | M9: =IF('Заполняет конвертор НЕ ТРОГАТЬ!'!A132="", "", 'Заполняет конвертор НЕ ТРОГАТЬ!'!A132) -> 46082 | N9: =IF('Заполняет конвертор НЕ ТРОГАТЬ!'!B132="", "", 'Заполняет конвертор НЕ ТРОГАТЬ!'!B132) -> 456 | O9: =IF('Заполняет конвертор НЕ ТРОГАТЬ!'!C132="", "", 'Заполняет конвертор НЕ ТРОГАТЬ!'!C132) -> 12 | P9: =IF('Заполняет конвертор НЕ ТРОГАТЬ!'!D132="", "", 'Заполняет конвертор НЕ ТРОГАТЬ!'!D132) -> 5 | Q9: =IF('Заполняет конвертор НЕ ТРОГАТЬ!'!E132="", "", 'Заполняет конвертор НЕ ТРОГАТЬ!'!E132) -> 52
A10: =M11 -> май 2026 | B10: =N11+P11 -> 434 | C10: =O11+Q11 -> 97 | D10: =IFERROR((B10-C10)/B10,0) -> 0.7764977 | E10: =IFERROR(C10/B10,0) -> 0.2235023 | M10: =IF('Заполняет конвертор НЕ ТРОГАТЬ!'!A133="", "", 'Заполняет конвертор НЕ ТРОГАТЬ!'!A133) -> 46113 | N10: =IF('Заполняет конвертор НЕ ТРОГАТЬ!'!B133="", "", 'Заполняет конвертор НЕ ТРОГАТЬ!'!B133) -> 313 | O10: =IF('Заполняет конвертор НЕ ТРОГАТЬ!'!C133="", "", 'Заполняет конвертор НЕ ТРОГАТЬ!'!C133) -> 11 | P10: =IF('Заполняет конвертор НЕ ТРОГАТЬ!'!D133="", "", 'Заполняет конвертор НЕ ТРОГАТЬ!'!D133) -> 4 | Q10: =IF('Заполняет конвертор НЕ ТРОГАТЬ!'!E133="", "", 'Заполняет конвертор НЕ ТРОГАТЬ!'!E133) -> 39
A11: =M12 -> 46174 | B11: =N12+P12 -> 370 | C11: =O12+Q12 -> 69 | D11: =IFERROR((B11-C11)/B11,0) -> 0.81351351 | E11: =IFERROR(C11/B11,0) -> 0.18648649 | M11: =IF('Заполняет конвертор НЕ ТРОГАТЬ!'!A134="", "", 'Заполняет конвертор НЕ ТРОГАТЬ!'!A134) -> май 2026 | N11: =IF('Заполняет конвертор НЕ ТРОГАТЬ!'!B134="", "", 'Заполняет конвертор НЕ ТРОГАТЬ!'!B134) -> 431 | O11: =IF('Заполняет конвертор НЕ ТРОГАТЬ!'!C134="", "", 'Заполняет конвертор НЕ ТРОГАТЬ!'!C134) -> 21 | P11: =IF('Заполняет конвертор НЕ ТРОГАТЬ!'!D134="", "", 'Заполняет конвертор НЕ ТРОГАТЬ!'!D134) -> 3 | Q11: =IF('Заполняет конвертор НЕ ТРОГАТЬ!'!E134="", "", 'Заполняет конвертор НЕ ТРОГАТЬ!'!E134) -> 76
A12: =M13 -> 46204 | B12: =N13+P13 -> 384 | C12: =O13+Q13 -> 35 | D12: =IFERROR((B12-C12)/B12,0) -> 0.90885417 | E12: =IFERROR(C12/B12,0) -> 0.091145833 | M12: =IF('Заполняет конвертор НЕ ТРОГАТЬ!'!A135="", "", 'Заполняет конвертор НЕ ТРОГАТЬ!'!A135) -> 46174 | N12: =IF('Заполняет конвертор НЕ ТРОГАТЬ!'!B135="", "", 'Заполняет конвертор НЕ ТРОГАТЬ!'!B135) -> 363 | O12: =IF('Заполняет конвертор НЕ ТРОГАТЬ!'!C135="", "", 'Заполняет конвертор НЕ ТРОГАТЬ!'!C135) -> 13 | P12: =IF('Заполняет конвертор НЕ ТРОГАТЬ!'!D135="", "", 'Заполняет конвертор НЕ ТРОГАТЬ!'!D135) -> 7 | Q12: =IF('Заполняет конвертор НЕ ТРОГАТЬ!'!E135="", "", 'Заполняет конвертор НЕ ТРОГАТЬ!'!E135) -> 56
A13: =M14 -> 46235 | B13: =N14+P14 -> 253 | C13: =O14+Q14 -> 13 | D13: =IFERROR((B13-C13)/B13,0) -> 0.9486166 | E13: =IFERROR(C13/B13,0) -> 0.051383399 | M13: =IF('Заполняет конвертор НЕ ТРОГАТЬ!'!A136="", "", 'Заполняет конвертор НЕ ТРОГАТЬ!'!A136) -> 46204 | N13: =IF('Заполняет конвертор НЕ ТРОГАТЬ!'!B136="", "", 'Заполняет конвертор НЕ ТРОГАТЬ!'!B136) -> 380 | O13: =IF('Заполняет конвертор НЕ ТРОГАТЬ!'!C136="", "", 'Заполняет конвертор НЕ ТРОГАТЬ!'!C136) -> 7 | P13: =IF('Заполняет конвертор НЕ ТРОГАТЬ!'!D136="", "", 'Заполняет конвертор НЕ ТРОГАТЬ!'!D136) -> 4 | Q13: =IF('Заполняет конвертор НЕ ТРОГАТЬ!'!E136="", "", 'Заполняет конвертор НЕ ТРОГАТЬ!'!E136) -> 28
A14: ИТОГО | B14: =SUM(B2:B13) -> 4845 | C14: =SUM(C2:C13) -> 695 | D14: =1-(C14/B14) -> 0.85655315 | E14: =C14/B14 -> 0.14344685 | M14: =IF('Заполняет конвертор НЕ ТРОГАТЬ!'!A137="", "", 'Заполняет конвертор НЕ ТРОГАТЬ!'!A137) -> 46235 | N14: =IF('Заполняет конвертор НЕ ТРОГАТЬ!'!B137="", "", 'Заполняет конвертор НЕ ТРОГАТЬ!'!B137) -> 252 | O14: =IF('Заполняет конвертор НЕ ТРОГАТЬ!'!C137="", "", 'Заполняет конвертор НЕ ТРОГАТЬ!'!C137) -> 2 | P14: =IF('Заполняет конвертор НЕ ТРОГАТЬ!'!D137="", "", 'Заполняет конвертор НЕ ТРОГАТЬ!'!D137) -> 1 | Q14: =IF('Заполняет конвертор НЕ ТРОГАТЬ!'!E137="", "", 'Заполняет конвертор НЕ ТРОГАТЬ!'!E137) -> 11
B15: B14 - формула | C15: С14 - формула
A17: Ссылка на отчет в Арке

Sheet Выбытие до 60 дней в доении
A1: Дата выбытия | B1: Прц | C1: Кол-в | E1: Ссылка на отчет в Арке | L1: Дата выбытия | M1: Продажа | N1: Падёж | P1: Сумма
A2: =A3-1 -> 46219 | C2: =IFERROR(_xlfn.XLOOKUP(A2,$L$2:$L$31,$P$2:$P$31),0) -> 0 | L2: =IF('Заполняет конвертор НЕ ТРОГАТЬ!'!S3="", "", 'Заполняет конвертор НЕ ТРОГАТЬ!'!S3) | M2: =IF('Заполняет конвертор НЕ ТРОГАТЬ!'!T3="", "", 'Заполняет конвертор НЕ ТРОГАТЬ!'!T3) -> 1 | N2: =IF('Заполняет конвертор НЕ ТРОГАТЬ!'!U3="", "", 'Заполняет конвертор НЕ ТРОГАТЬ!'!U3) | P2: =M2+N2 -> #VALUE!
A3: =A4-1 -> 46220 | C3: =IFERROR(_xlfn.XLOOKUP(A3,$L$2:$L$31,$P$2:$P$31),0) -> 0 | L3: =IF('Заполняет конвертор НЕ ТРОГАТЬ!'!S4="", "", 'Заполняет конвертор НЕ ТРОГАТЬ!'!S4) | M3: =IF('Заполняет конвертор НЕ ТРОГАТЬ!'!T4="", "", 'Заполняет конвертор НЕ ТРОГАТЬ!'!T4) | N3: =IF('Заполняет конвертор НЕ ТРОГАТЬ!'!U4="", "", 'Заполняет конвертор НЕ ТРОГАТЬ!'!U4) | P3: =M3+N3 -> #VALUE!
A4: =A5-1 -> 46221 | C4: =IFERROR(_xlfn.XLOOKUP(A4,$L$2:$L$31,$P$2:$P$31),0) -> 0 | L4: =IF('Заполняет конвертор НЕ ТРОГАТЬ!'!S5="", "", 'Заполняет конвертор НЕ ТРОГАТЬ!'!S5) | M4: =IF('Заполняет конвертор НЕ ТРОГАТЬ!'!T5="", "", 'Заполняет конвертор НЕ ТРОГАТЬ!'!T5) | N4: =IF('Заполняет конвертор НЕ ТРОГАТЬ!'!U5="", "", 'Заполняет конвертор НЕ ТРОГАТЬ!'!U5) | P4: =M4+N4 -> #VALUE!
A5: =A6-1 -> 46222 | C5: =IFERROR(_xlfn.XLOOKUP(A5,$L$2:$L$31,$P$2:$P$31),0) -> 0 | L5: =IF('Заполняет конвертор НЕ ТРОГАТЬ!'!S6="", "", 'Заполняет конвертор НЕ ТРОГАТЬ!'!S6) | M5: =IF('Заполняет конвертор НЕ ТРОГАТЬ!'!T6="", "", 'Заполняет конвертор НЕ ТРОГАТЬ!'!T6) | N5: =IF('Заполняет конвертор НЕ ТРОГАТЬ!'!U6="", "", 'Заполняет конвертор НЕ ТРОГАТЬ!'!U6) | P5: =M5+N5 -> #VALUE!
A6: =A7-1 -> 46223 | C6: =IFERROR(_xlfn.XLOOKUP(A6,$L$2:$L$31,$P$2:$P$31),0) -> 0 | L6: =IF('Заполняет конвертор НЕ ТРОГАТЬ!'!S7="", "", 'Заполняет конвертор НЕ ТРОГАТЬ!'!S7) | M6: =IF('Заполняет конвертор НЕ ТРОГАТЬ!'!T7="", "", 'Заполняет конвертор НЕ ТРОГАТЬ!'!T7) | N6: =IF('Заполняет конвертор НЕ ТРОГАТЬ!'!U7="", "", 'Заполняет конвертор НЕ ТРОГАТЬ!'!U7) | P6: =M6+N6 -> #VALUE!
A7: =A8-1 -> 46224 | C7: =IFERROR(_xlfn.XLOOKUP(A7,$L$2:$L$31,$P$2:$P$31),0) -> 0 | L7: =IF('Заполняет конвертор НЕ ТРОГАТЬ!'!S8="", "", 'Заполняет конвертор НЕ ТРОГАТЬ!'!S8) | M7: =IF('Заполняет конвертор НЕ ТРОГАТЬ!'!T8="", "", 'Заполняет конвертор НЕ ТРОГАТЬ!'!T8) | N7: =IF('Заполняет конвертор НЕ ТРОГАТЬ!'!U8="", "", 'Заполняет конвертор НЕ ТРОГАТЬ!'!U8) | P7: =M7+N7 -> #VALUE!
A8: =A9-1 -> 46225 | C8: =IFERROR(_xlfn.XLOOKUP(A8,$L$2:$L$31,$P$2:$P$31),0) -> 0 | L8: =IF('Заполняет конвертор НЕ ТРОГАТЬ!'!S9="", "", 'Заполняет конвертор НЕ ТРОГАТЬ!'!S9) | M8: =IF('Заполняет конвертор НЕ ТРОГАТЬ!'!T9="", "", 'Заполняет конвертор НЕ ТРОГАТЬ!'!T9) | N8: =IF('Заполняет конвертор НЕ ТРОГАТЬ!'!U9="", "", 'Заполняет конвертор НЕ ТРОГАТЬ!'!U9) | P8: =M8+N8 -> #VALUE!
